Workbook

Sheet ריכוז שעות
E1: אריאל ספא בע"מ
E2: A+ סטריט מול בע"מ
A3: שעות פעילות חד"כ | B3: 0.79166667 | C3: 0.33333333
D5: נוכחות | E5: יוני | F5: 46174
A7: יום | B7: יום | C7: חג | D7: משמרת בוקר | E7: משמרת ערב סגירה | F7: סה"כ
A8: בחודש | B8: בשבוע | C8: וימים מיוחדים | F8: שעות עבודה | G8: הערות
A9: 46174 | B9: =TEXT(A9,"dddd") -> Monday | C9: =VLOOKUP(A9,חגים!$A$2:$C$794,2,FALSE) -> #N/A | D9: =IF(B9=$N$26, $N$18, IF(B9=$N$27, $N$19, IF(OR(B9=$N$21, B9=$N$22, B9=$N$23, B9=$N$24, B9=$N$25), $N$17, "ERR"))) -> ERR | E9: =IF(OR(B9=$M$26,B9=$M$27),"CLOSED",IF(OR(B9=$M$21,B9=$M$22,B9=$M$23,B9=$M$24,B9=$M$25),$O$17,"ERR")) -> ERR | F9: =IF(OR(B9=$M$26),$N$26,IF(OR(B9=$M$27),$N$27,IF(OR(B9=$M$21,B9=$M$22,B9=$M$23,B9=$M$24,B9=$M$25),$N$21,"ERR"))) -> ERR
A10: 46175 | B10: =TEXT(A10,"dddd") -> Tuesday | C10: =VLOOKUP(A10,חגים!$A$2:$C$794,2,FALSE) -> #N/A | D10: =IF(OR(B10=$M$26),$M$18,IF(OR(B10=$M$27),$M$19,IF(OR(B10=$M$21,B10=$M$22,B10=$M$23,B10=$M$24,B10=$M$25),$M$17,"ERR"))) -> ERR | E10: =IF(OR(B10=$M$26,B10=$M$27),"CLOSED",IF(OR(B10=$M$21,B10=$M$22,B10=$M$23,B10=$M$24,B10=$M$25),$O$17,"ERR")) -> ERR | F10: =IF(OR(B10=$M$26),$N$26,IF(OR(B10=$M$27),$N$27,IF(OR(B10=$M$21,B10=$M$22,B10=$M$23,B10=$M$24,B10=$M$25),$N$21,"ERR"))) -> ERR
A11: 46176 | B11: =TEXT(A11,"dddd") -> Wednesday | C11: =VLOOKUP(A11,חגים!$A$2:$C$794,2,FALSE) -> #N/A | D11: =IF(OR(B11=$M$26),$M$18,IF(OR(B11=$M$27),$M$19,IF(OR(B11=$M$21,B11=$M$22,B11=$M$23,B11=$M$24,B11=$M$25),$M$17,"ERR"))) -> ERR | E11: =IF(OR(B11=$M$26,B11=$M$27),"CLOSED",IF(OR(B11=$M$21,B11=$M$22,B11=$M$23,B11=$M$24,B11=$M$25),$O$17,"ERR")) -> ERR | F11: =IF(OR(B11=$M$26),$N$26,IF(OR(B11=$M$27),$N$27,IF(OR(B11=$M$21,B11=$M$22,B11=$M$23,B11=$M$24,B11=$M$25),$N$21,"ERR"))) -> ERR
A12: 46177 | B12: =TEXT(A12,"dddd") -> Thursday | C12: =VLOOKUP(A12,חגים!$A$2:$C$794,2,FALSE) -> #N/A | D12: =IF(OR(B12=$M$26),$M$18,IF(OR(B12=$M$27),$M$19,IF(OR(B12=$M$21,B12=$M$22,B12=$M$23,B12=$M$24,B12=$M$25),$M$17,"ERR"))) -> ERR | E12: =IF(OR(B12=$M$26,B12=$M$27),"CLOSED",IF(OR(B12=$M$21,B12=$M$22,B12=$M$23,B12=$M$24,B12=$M$25),$O$17,"ERR")) -> ERR | F12: =IF(OR(B12=$M$26),$N$26,IF(OR(B12=$M$27),$N$27,IF(OR(B12=$M$21,B12=$M$22,B12=$M$23,B12=$M$24,B12=$M$25),$N$21,"ERR"))) -> ERR
A13: 46178 | B13: =TEXT(A13,"dddd") -> Friday | C13: =VLOOKUP(A13,חגים!$A$2:$C$794,2,FALSE) -> #N/A | D13: =IF(OR(B13=$M$26),$M$18,IF(OR(B13=$M$27),$M$19,IF(OR(B13=$M$21,B13=$M$22,B13=$M$23,B13=$M$24,B13=$M$25),$M$17,"ERR"))) -> ERR | E13: =IF(OR(B13=$M$26,B13=$M$27),"CLOSED",IF(OR(B13=$M$21,B13=$M$22,B13=$M$23,B13=$M$24,B13=$M$25),$O$17,"ERR")) -> ERR | F13: =IF(OR(B13=$M$26),$N$26,IF(OR(B13=$M$27),$N$27,IF(OR(B13=$M$21,B13=$M$22,B13=$M$23,B13=$M$24,B13=$M$25),$N$21,"ERR"))) -> ERR
A14: 46179 | B14: =TEXT(A14,"dddd") -> Saturday | C14: =VLOOKUP(A14,חגים!$A$2:$C$794,2,FALSE) -> #N/A | D14: =IF(OR(B14=$M$26),$M$18,IF(OR(B14=$M$27),$M$19,IF(OR(B14=$M$21,B14=$M$22,B14=$M$23,B14=$M$24,B14=$M$25),$M$17,"ERR"))) -> ERR | E14: =IF(OR(B14=$M$26,B14=$M$27),"CLOSED",IF(OR(B14=$M$21,B14=$M$22,B14=$M$23,B14=$M$24,B14=$M$25),$O$17,"ERR")) -> ERR | F14: =IF(OR(B14=$M$26),$N$26,IF(OR(B14=$M$27),$N$27,IF(OR(B14=$M$21,B14=$M$22,B14=$M$23,B14=$M$24,B14=$M$25),$N$21,"ERR"))) -> ERR
A15: 46180 | B15: =TEXT(A15,"dddd") -> Sunday | C15: =VLOOKUP(A15,חגים!$A$2:$C$794,2,FALSE) -> #N/A | D15: =IF(OR(B15=$M$26),$M$18,IF(OR(B15=$M$27),$M$19,IF(OR(B15=$M$21,B15=$M$22,B15=$M$23,B15=$M$24,B15=$M$25),$M$17,"ERR"))) -> ERR | E15: =IF(OR(B15=$M$26,B15=$M$27),"CLOSED",IF(OR(B15=$M$21,B15=$M$22,B15=$M$23,B15=$M$24,B15=$M$25),$O$17,"ERR")) -> ERR | F15: =IF(OR(B15=$M$26),$N$26,IF(OR(B15=$M$27),$N$27,IF(OR(B15=$M$21,B15=$M$22,B15=$M$23,B15=$M$24,B15=$M$25),$N$21,"ERR"))) -> ERR
A16: 46181 | B16: =TEXT(A16,"dddd") -> Monday | C16: =VLOOKUP(A16,חגים!$A$2:$C$794,2,FALSE) -> #N/A | D16: =IF(OR(B16=$M$26),$M$18,IF(OR(B16=$M$27),$M$19,IF(OR(B16=$M$21,B16=$M$22,B16=$M$23,B16=$M$24,B16=$M$25),$M$17,"ERR"))) -> ERR | E16: =IF(OR(B16=$M$26,B16=$M$27),"CLOSED",IF(OR(B16=$M$21,B16=$M$22,B16=$M$23,B16=$M$24,B16=$M$25),$O$17,"ERR")) -> ERR | F16: =IF(OR(B16=$M$26),$N$26,IF(OR(B16=$M$27),$N$27,IF(OR(B16=$M$21,B16=$M$22,B16=$M$23,B16=$M$24,B16=$M$25),$N$21,"ERR"))) -> ERR | M16: בוקר | N16: ע.ארוכה | O16: ע.סגירה
A17: 46182 | B17: =TEXT(A17,"dddd") -> Tuesday | C17: =VLOOKUP(A17,חגים!$A$2:$C$794,2,FALSE) -> #N/A | D17: =IF(OR(B17=$M$26),$M$18,IF(OR(B17=$M$27),$M$19,IF(OR(B17=$M$21,B17=$M$22,B17=$M$23,B17=$M$24,B17=$M$25),$M$17,"ERR"))) -> ERR | E17: =IF(OR(B17=$M$26,B17=$M$27),"CLOSED",IF(OR(B17=$M$21,B17=$M$22,B17=$M$23,B17=$M$24,B17=$M$25),$O$17,"ERR")) -> ERR | F17: =IF(OR(B17=$M$26),$N$26,IF(OR(B17=$M$27),$N$27,IF(OR(B17=$M$21,B17=$M$22,B17=$M$23,B17=$M$24,B17=$M$25),$N$21,"ERR"))) -> ERR | K17: ראשון - חמישי | M17: 08:00-11:00 | O17: 17:00-20:00
A18: 46183 | B18: =TEXT(A18,"dddd") -> Wednesday | C18: =VLOOKUP(A18,חגים!$A$2:$C$794,2,FALSE) -> #N/A | D18: =IF(OR(B18=$M$26),$M$18,IF(OR(B18=$M$27),$M$19,IF(OR(B18=$M$21,B18=$M$22,B18=$M$23,B18=$M$24,B18=$M$25),$M$17,"ERR"))) -> ERR | E18: =IF(OR(B18=$M$26,B18=$M$27),"CLOSED",IF(OR(B18=$M$21,B18=$M$22,B18=$M$23,B18=$M$24,B18=$M$25),$O$17,"ERR")) -> ERR | F18: =IF(OR(B18=$M$26),$N$26,IF(OR(B18=$M$27),$N$27,IF(OR(B18=$M$21,B18=$M$22,B18=$M$23,B18=$M$24,B18=$M$25),$N$21,"ERR"))) -> ERR | K18: שישי | M18: 08:00-12:00
A19: 46184 | B19: =TEXT(A19,"dddd") -> Thursday | C19: =VLOOKUP(A19,חגים!$A$2:$C$794,2,FALSE) -> #N/A | D19: =IF(OR(B19=$M$26),$M$18,IF(OR(B19=$M$27),$M$19,IF(OR(B19=$M$21,B19=$M$22,B19=$M$23,B19=$M$24,B19=$M$25),$M$17,"ERR"))) -> ERR | E19: =IF(OR(B19=$M$26,B19=$M$27),"CLOSED",IF(OR(B19=$M$21,B19=$M$22,B19=$M$23,B19=$M$24,B19=$M$25),$O$17,"ERR")) -> ERR | F19: =IF(OR(B19=$M$26),$N$26,IF(OR(B19=$M$27),$N$27,IF(OR(B19=$M$21,B19=$M$22,B19=$M$23,B19=$M$24,B19=$M$25),$N$21,"ERR"))) -> ERR | K19: שבת
A20: 46185 | B20: =TEXT(A20,"dddd") -> Friday | C20: =VLOOKUP(A20,חגים!$A$2:$C$794,2,FALSE) -> #N/A | D20: =IF(OR(B20=$M$26),$M$18,IF(OR(B20=$M$27),$M$19,IF(OR(B20=$M$21,B20=$M$22,B20=$M$23,B20=$M$24,B20=$M$25),$M$17,"ERR"))) -> ERR | E20: =IF(OR(B20=$M$26,B20=$M$27),"CLOSED",IF(OR(B20=$M$21,B20=$M$22,B20=$M$23,B20=$M$24,B20=$M$25),$O$17,"ERR")) -> ERR | F20: =IF(OR(B20=$M$26),$N$26,IF(OR(B20=$M$27),$N$27,IF(OR(B20=$M$21,B20=$M$22,B20=$M$23,B20=$M$24,B20=$M$25),$N$21,"ERR"))) -> ERR
A21: 46186 | B21: =TEXT(A21,"dddd") -> Saturday | C21: =VLOOKUP(A21,חגים!$A$2:$C$794,2,FALSE) -> #N/A | D21: =IF(OR(B21=$M$26),$M$18,IF(OR(B21=$M$27),$M$19,IF(OR(B21=$M$21,B21=$M$22,B21=$M$23,B21=$M$24,B21=$M$25),$M$17,"ERR"))) -> ERR | E21: =IF(OR(B21=$M$26,B21=$M$27),"CLOSED",IF(OR(B21=$M$21,B21=$M$22,B21=$M$23,B21=$M$24,B21=$M$25),$O$17,"ERR")) -> ERR | F21: =IF(OR(B21=$M$26),$N$26,IF(OR(B21=$M$27),$N$27,IF(OR(B21=$M$21,B21=$M$22,B21=$M$23,B21=$M$24,B21=$M$25),$N$21,"ERR"))) -> ERR | M21: יום ראשון | N21: 7
A22: 46187 | B22: =TEXT(A22,"dddd") -> Sunday | C22: =VLOOKUP(A22,חגים!$A$2:$C$794,2,FALSE) -> #N/A | D22: =IF(OR(B22=$M$26),$M$18,IF(OR(B22=$M$27),$M$19,IF(OR(B22=$M$21,B22=$M$22,B22=$M$23,B22=$M$24,B22=$M$25),$M$17,"ERR"))) -> ERR | E22: =IF(OR(B22=$M$26,B22=$M$27),"CLOSED",IF(OR(B22=$M$21,B22=$M$22,B22=$M$23,B22=$M$24,B22=$M$25),$O$17,"ERR")) -> ERR | F22: =IF(OR(B22=$M$26),$N$26,IF(OR(B22=$M$27),$N$27,IF(OR(B22=$M$21,B22=$M$22,B22=$M$23,B22=$M$24,B22=$M$25),$N$21,"ERR"))) -> ERR | M22: יום שני | N22: 6 | P22: ינואר | Q22: נורמאטיבי
A23: 46188 | B23: =TEXT(A23,"dddd") -> Monday | C23: =VLOOKUP(A23,חגים!$A$2:$C$794,2,FALSE) -> #N/A | D23: =IF(OR(B23=$M$26),$M$18,IF(OR(B23=$M$27),$M$19,IF(OR(B23=$M$21,B23=$M$22,B23=$M$23,B23=$M$24,B23=$M$25),$M$17,"ERR"))) -> ERR | E23: =IF(OR(B23=$M$26,B23=$M$27),"CLOSED",IF(OR(B23=$M$21,B23=$M$22,B23=$M$23,B23=$M$24,B23=$M$25),$O$17,"ERR")) -> ERR | F23: =IF(OR(B23=$M$26),$N$26,IF(OR(B23=$M$27),$N$27,IF(OR(B23=$M$21,B23=$M$22,B23=$M$23,B23=$M$24,B23=$M$25),$N$21,"ERR"))) -> ERR | M23: יום שלישי | N23: 6 | Q23: שעות | R23: מס' שעות | S23: מס' עובדים
A24: 46189 | B24: =TEXT(A24,"dddd") -> Tuesday | C24: =VLOOKUP(A24,חגים!$A$2:$C$794,2,FALSE) -> #N/A | D24: =IF(OR(B24=$M$26),$M$18,IF(OR(B24=$M$27),$M$19,IF(OR(B24=$M$21,B24=$M$22,B24=$M$23,B24=$M$24,B24=$M$25),$M$17,"ERR"))) -> ERR | E24: =IF(OR(B24=$M$26,B24=$M$27),"CLOSED",IF(OR(B24=$M$21,B24=$M$22,B24=$M$23,B24=$M$24,B24=$M$25),$O$17,"ERR")) -> ERR | F24: =IF(OR(B24=$M$26),$N$26,IF(OR(B24=$M$27),$N$27,IF(OR(B24=$M$21,B24=$M$22,B24=$M$23,B24=$M$24,B24=$M$25),$N$21,"ERR"))) -> ERR | M24: יום רביעי | N24: 6 | P24: א - ה | Q24: 08:00-11:00 | R24: 3 | S24: 1
A25: 46190 | B25: =TEXT(A25,"dddd") -> Wednesday | C25: =VLOOKUP(A25,חגים!$A$2:$C$794,2,FALSE) -> #N/A | D25: =IF(OR(B25=$M$26),$M$18,IF(OR(B25=$M$27),$M$19,IF(OR(B25=$M$21,B25=$M$22,B25=$M$23,B25=$M$24,B25=$M$25),$M$17,"ERR"))) -> ERR | E25: =IF(OR(B25=$M$26,B25=$M$27),"CLOSED",IF(OR(B25=$M$21,B25=$M$22,B25=$M$23,B25=$M$24,B25=$M$25),$O$17,"ERR")) -> ERR | F25: =IF(OR(B25=$M$26),$N$26,IF(OR(B25=$M$27),$N$27,IF(OR(B25=$M$21,B25=$M$22,B25=$M$23,B25=$M$24,B25=$M$25),$N$21,"ERR"))) -> ERR | M25: יום חמישי | N25: 6 | P25: ראשון | Q25: 16:30-20:30 | R25: 4 | S25: 1
A26: 46191 | B26: =TEXT(A26,"dddd") -> Thursday | C26: =VLOOKUP(A26,חגים!$A$2:$C$794,2,FALSE) -> #N/A | D26: =IF(OR(B26=$M$26),$M$18,IF(OR(B26=$M$27),$M$19,IF(OR(B26=$M$21,B26=$M$22,B26=$M$23,B26=$M$24,B26=$M$25),$M$17,"ERR"))) -> ERR | E26: =IF(OR(B26=$M$26,B26=$M$27),"CLOSED",IF(OR(B26=$M$21,B26=$M$22,B26=$M$23,B26=$M$24,B26=$M$25),$O$17,"ERR")) -> ERR | F26: =IF(OR(B26=$M$26),$N$26,IF(OR(B26=$M$27),$N$27,IF(OR(B26=$M$21,B26=$M$22,B26=$M$23,B26=$M$24,B26=$M$25),$N$21,"ERR"))) -> ERR | M26: יום שישי | N26: 4 | P26: ב - ה | Q26: 17:00-20:00 | R26: 3
A27: 46192 | B27: =TEXT(A27,"dddd") -> Friday | C27: =VLOOKUP(A27,חגים!$A$2:$C$794,2,FALSE) -> #N/A | D27: =IF(OR(B27=$M$26),$M$18,IF(OR(B27=$M$27),$M$19,IF(OR(B27=$M$21,B27=$M$22,B27=$M$23,B27=$M$24,B27=$M$25),$M$17,"ERR"))) -> ERR | E27: =IF(OR(B27=$M$26,B27=$M$27),"CLOSED",IF(OR(B27=$M$21,B27=$M$22,B27=$M$23,B27=$M$24,B27=$M$25),$O$17,"ERR")) -> ERR | F27: =IF(OR(B27=$M$26),$N$26,IF(OR(B27=$M$27),$N$27,IF(OR(B27=$M$21,B27=$M$22,B27=$M$23,B27=$M$24,B27=$M$25),$N$21,"ERR"))) -> ERR | M27: שבת | P27: שישי | Q27: 08:00-12:00 | R27: 4 | S27: 1
A28: 46193 | B28: =TEXT(A28,"dddd") -> Saturday | C28: =VLOOKUP(A28,חגים!$A$2:$C$794,2,FALSE) -> #N/A | D28: =IF(OR(B28=$M$26),$M$18,IF(OR(B28=$M$27),$M$19,IF(OR(B28=$M$21,B28=$M$22,B28=$M$23,B28=$M$24,B28=$M$25),$M$17,"ERR"))) -> ERR | E28: =IF(OR(B28=$M$26,B28=$M$27),"CLOSED",IF(OR(B28=$M$21,B28=$M$22,B28=$M$23,B28=$M$24,B28=$M$25),$O$17,"ERR")) -> ERR | F28: =IF(OR(B28=$M$26),$N$26,IF(OR(B28=$M$27),$N$27,IF(OR(B28=$M$21,B28=$M$22,B28=$M$23,B28=$M$24,B28=$M$25),$N$21,"ERR"))) -> ERR
A29: 46194 | B29: =TEXT(A29,"dddd") -> Sunday | C29: =VLOOKUP(A29,חגים!$A$2:$C$794,2,FALSE) -> #N/A | D29: =IF(OR(B29=$M$26),$M$18,IF(OR(B29=$M$27),$M$19,IF(OR(B29=$M$21,B29=$M$22,B29=$M$23,B29=$M$24,B29=$M$25),$M$17,"ERR"))) -> ERR | E29: =IF(OR(B29=$M$26,B29=$M$27),"CLOSED",IF(OR(B29=$M$21,B29=$M$22,B29=$M$23,B29=$M$24,B29=$M$25),$O$17,"ERR")) -> ERR | F29: =IF(OR(B29=$M$26),$N$26,IF(OR(B29=$M$27),$N$27,IF(OR(B29=$M$21,B29=$M$22,B29=$M$23,B29=$M$24,B29=$M$25),$N$21,"ERR"))) -> ERR
A30: 46195 | B30: =TEXT(A30,"dddd") -> Monday | C30: =VLOOKUP(A30,חגים!$A$2:$C$794,2,FALSE) -> #N/A | D30: =IF(OR(B30=$M$26),$M$18,IF(OR(B30=$M$27),$M$19,IF(OR(B30=$M$21,B30=$M$22,B30=$M$23,B30=$M$24,B30=$M$25),$M$17,"ERR"))) -> ERR | E30: =IF(OR(B30=$M$26,B30=$M$27),"CLOSED",IF(OR(B30=$M$21,B30=$M$22,B30=$M$23,B30=$M$24,B30=$M$25),$O$17,"ERR")) -> ERR | F30: =IF(OR(B30=$M$26),$N$26,IF(OR(B30=$M$27),$N$27,IF(OR(B30=$M$21,B30=$M$22,B30=$M$23,B30=$M$24,B30=$M$25),$N$21,"ERR"))) -> ERR | P30: שבת
A31: 46196 | B31: =TEXT(A31,"dddd") -> Tuesday | C31: =VLOOKUP(A31,חגים!$A$2:$C$794,2,FALSE) -> #N/A | D31: =IF(OR(B31=$M$26),$M$18,IF(OR(B31=$M$27),$M$19,IF(OR(B31=$M$21,B31=$M$22,B31=$M$23,B31=$M$24,B31=$M$25),$M$17,"ERR"))) -> ERR | E31: =IF(OR(B31=$M$26,B31=$M$27),"CLOSED",IF(OR(B31=$M$21,B31=$M$22,B31=$M$23,B31=$M$24,B31=$M$25),$O$17,"ERR")) -> ERR | F31: =IF(OR(B31=$M$26),$N$26,IF(OR(B31=$M$27),$N$27,IF(OR(B31=$M$21,B31=$M$22,B31=$M$23,B31=$M$24,B31=$M$25),$N$21,"ERR"))) -> ERR
A32: 46197 | B32: =TEXT(A32,"dddd") -> Wednesday | C32: =VLOOKUP(A32,חגים!$A$2:$C$794,2,FALSE) -> #N/A | D32: =IF(OR(B32=$M$26),$M$18,IF(OR(B32=$M$27),$M$19,IF(OR(B32=$M$21,B32=$M$22,B32=$M$23,B32=$M$24,B32=$M$25),$M$17,"ERR"))) -> ERR | E32: =IF(OR(B32=$M$26,B32=$M$27),"CLOSED",IF(OR(B32=$M$21,B32=$M$22,B32=$M$23,B32=$M$24,B32=$M$25),$O$17,"ERR")) -> ERR | F32: =IF(OR(B32=$M$26),$N$26,IF(OR(B32=$M$27),$N$27,IF(OR(B32=$M$21,B32=$M$22,B32=$M$23,B32=$M$24,B32=$M$25),$N$21,"ERR"))) -> ERR
A33: 46198 | B33: =TEXT(A33,"dddd") -> Thursday | C33: =VLOOKUP(A33,חגים!$A$2:$C$794,2,FALSE) -> #N/A | D33: =IF(OR(B33=$M$26),$M$18,IF(OR(B33=$M$27),$M$19,IF(OR(B33=$M$21,B33=$M$22,B33=$M$23,B33=$M$24,B33=$M$25),$M$17,"ERR"))) -> ERR | E33: =IF(OR(B33=$M$26,B33=$M$27),"CLOSED",IF(OR(B33=$M$21,B33=$M$22,B33=$M$23,B33=$M$24,B33=$M$25),$O$17,"ERR")) -> ERR | F33: =IF(OR(B33=$M$26),$N$26,IF(OR(B33=$M$27),$N$27,IF(OR(B33=$M$21,B33=$M$22,B33=$M$23,B33=$M$24,B33=$M$25),$N$21,"ERR"))) -> ERR
A34: 46199 | B34: =TEXT(A34,"dddd") -> Friday | C34: =VLOOKUP(A34,חגים!$A$2:$C$794,2,FALSE) -> #N/A | D34: =IF(OR(B34=$M$26),$M$18,IF(OR(B34=$M$27),$M$19,IF(OR(B34=$M$21,B34=$M$22,B34=$M$23,B34=$M$24,B34=$M$25),$M$17,"ERR"))) -> ERR | E34: =IF(OR(B34=$M$26,B34=$M$27),"CLOSED",IF(OR(B34=$M$21,B34=$M$22,B34=$M$23,B34=$M$24,B34=$M$25),$O$17,"ERR")) -> ERR | F34: =IF(OR(B34=$M$26),$N$26,IF(OR(B34=$M$27),$N$27,IF(OR(B34=$M$21,B34=$M$22,B34=$M$23,B34=$M$24,B34=$M$25),$N$21,"ERR"))) -> ERR
A35: 46200 | B35: =TEXT(A35,"dddd") -> Saturday | C35: =VLOOKUP(A35,חגים!$A$2:$C$794,2,FALSE) -> #N/A | D35: =IF(OR(B35=$M$26),$M$18,IF(OR(B35=$M$27),$M$19,IF(OR(B35=$M$21,B35=$M$22,B35=$M$23,B35=$M$24,B35=$M$25),$M$17,"ERR"))) -> ERR | E35: =IF(OR(B35=$M$26,B35=$M$27),"CLOSED",IF(OR(B35=$M$21,B35=$M$22,B35=$M$23,B35=$M$24,B35=$M$25),$O$17,"ERR")) -> ERR | F35: =IF(OR(B35=$M$26),$N$26,IF(OR(B35=$M$27),$N$27,IF(OR(B35=$M$21,B35=$M$22,B35=$M$23,B35=$M$24,B35=$M$25),$N$21,"ERR"))) -> ERR
A36: 46201 | B36: =TEXT(A36,"dddd") -> Sunday | C36: =VLOOKUP(A36,חגים!$A$2:$C$794,2,FALSE) -> #N/A | D36: =IF(OR(B36=$M$26),$M$18,IF(OR(B36=$M$27),$M$19,IF(OR(B36=$M$21,B36=$M$22,B36=$M$23,B36=$M$24,B36=$M$25),$M$17,"ERR"))) -> ERR | E36: =IF(OR(B36=$M$26,B36=$M$27),"CLOSED",IF(OR(B36=$M$21,B36=$M$22,B36=$M$23,B36=$M$24,B36=$M$25),$O$17,"ERR")) -> ERR | F36: =IF(OR(B36=$M$26),$N$26,IF(OR(B36=$M$27),$N$27,IF(OR(B36=$M$21,B36=$M$22,B36=$M$23,B36=$M$24,B36=$M$25),$N$21,"ERR"))) -> ERR | L36: 0.70833333 | M36: 0.875
A37: 46202 | B37: =TEXT(A37,"dddd") -> Monday | C37: =VLOOKUP(A37,חגים!$A$2:$C$794,2,FALSE) -> #N/A | D37: =IF(OR(B37=$M$26),$M$18,IF(OR(B37=$M$27),$M$19,IF(OR(B37=$M$21,B37=$M$22,B37=$M$23,B37=$M$24,B37=$M$25),$M$17,"ERR"))) -> ERR | E37: =IF(OR(B37=$M$26,B37=$M$27),"CLOSED",IF(OR(B37=$M$21,B37=$M$22,B37=$M$23,B37=$M$24,B37=$M$25),$O$17,"ERR")) -> ERR | F37: =IF(OR(B37=$M$26),$N$26,IF(OR(B37=$M$27),$N$27,IF(OR(B37=$M$21,B37=$M$22,B37=$M$23,B37=$M$24,B37=$M$25),$N$21,"ERR"))) -> ERR
A38: 46203 | B38: =TEXT(A38,"dddd") -> Tuesday | C38: =VLOOKUP(A38,חגים!$A$2:$C$794,2,FALSE) -> #N/A | D38: =IF(OR(B38=$M$26),$M$18,IF(OR(B38=$M$27),$M$19,IF(OR(B38=$M$21,B38=$M$22,B38=$M$23,B38=$M$24,B38=$M$25),$M$17,"ERR"))) -> ERR | E38: =IF(OR(B38=$M$26,B38=$M$27),"CLOSED",IF(OR(B38=$M$21,B38=$M$22,B38=$M$23,B38=$M$24,B38=$M$25),$O$17,"ERR")) -> ERR | F38: =IF(OR(B38=$M$26),$N$26,IF(OR(B38=$M$27),$N$27,IF(OR(B38=$M$21,B38=$M$22,B38=$M$23,B38=$M$24,B38=$M$25),$N$21,"ERR"))) -> ERR
A39: 46204 | B39: =TEXT(A39,"dddd") -> Wednesday | C39: =VLOOKUP(A39,חגים!$A$2:$C$794,2,FALSE) -> #N/A | D39: =IF(OR(B39=$M$26),$M$18,IF(OR(B39=$M$27),$M$19,IF(OR(B39=$M$21,B39=$M$22,B39=$M$23,B39=$M$24,B39=$M$25),$M$17,"ERR"))) -> ERR | E39: =IF(OR(B39=$M$26,B39=$M$27),"CLOSED",IF(OR(B39=$M$21,B39=$M$22,B39=$M$23,B39=$M$24,B39=$M$25),$O$17,"ERR")) -> ERR | F39: =IF(OR(B39=$M$26),$N$26,IF(OR(B39=$M$27),$N$27,IF(OR(B39=$M$21,B39=$M$22,B39=$M$23,B39=$M$24,B39=$M$25),$N$21,"ERR"))) -> ERR
G40: =SUM(F9:F39) -> 0 | N40: 0.875
E41: אריאל ספא בע"מ | N41: 0.83333333
N42: 0.91666667
...

Sheet דוח מרכז לאישור מנהל
A1: A+ סטריט מול
A2: נוכחות יולי 2026
A4: שם העובד : | B4: נעמה חיון | C4: ניקול איידלמן | D4: סה"כ | E4: סה"כ לחיוב
A5: פירוט | B5: פילאטיס | C5: קבלה
A6: שעות רגילות | B6: 55 | C6: 83.75 | D6: =SUM(B6:C6) -> 138.75
A7: תעריף לפי 125% | C7: 3.25 | D7: =SUM(B7:C7) -> 3.25
A8: תעריף לפי 150% | D8: =SUM(B8:C8) -> 0
A9: תעריף לפי 175% | D9: =SUM(B9:C9) -> 0
A10: תעריף לפי 200% | D10: =SUM(B10:C10) -> 0
A11: שעות ישיבות והשתלמויות | D11: =SUM(B11:C11) -> 0
A12: תשלום נסיעות בפועל | B12: 208.5 | C12: 200 | D12: =SUM(B12:C12) -> 408.5 | E12: =SUM(B12:C12) -> 408.5
A13: שונות (בונוס) | D13: =SUM(B13:C13) -> 0
A14: סה"כ שעות אימון סטודיו פילאטיס | B14: ='סיכום אימונים ומכירות מנויים'!C13 -> 55 | D14: =SUMIF(B14:C14,">0") -> 55
A15: סה"כ שעות אימון אישי סטודיו פילאטיס | B15: ='סיכום אימונים ומכירות מנויים'!D13 -> 0 | D15: =SUMIF(B15:C15,">0") -> 0
A16: סה"כ שעות אימוני סטודיו | D16: =SUMIF(B16:C16,">0") -> 0
A17: סה"כ שעות אימוני קבוצות במשמרת | D17: =SUMIF(B17:C17,">0") -> 0
A18: סה"כ שעות אימוני קבוצות לא במשמרת | D18: =SUMIF(B18:C18,">0") -> 0
A19: סה"כ שעות אירוע חברה | D19: =SUMIF(B19:C19,">0") -> 0
A20: חיוב ימי עיון והשתלמות | E20: =SUM(B20:C20) -> 0
A21: חיוב שעות עבודה מכירות סטודיו פילאטיס | C21: =C6*$E$32 -> 5862.5 | E21: =SUM(B21:C21) -> 5862.5
A22: חיוב אימוני קבוצות | E22: =SUM(B22:C22) -> 0
A23: חיוב אימון סטודיו פילאטיס | B23: =B14*$I$32 -> 10175 | E23: =SUM(B23:C23) -> 10175
A24: חיוב אימון אישי סטודיו פילאטיס | B24: =B15*$I$32 -> 0 | E24: =SUM(B24:C24) -> 0
B25: =SUM(B20:B24)+B12 -> 10383.5 | C25: =SUM(C20:C24)+C12 -> 6062.5
A26: מכירות | B26: ='סיכום אימונים ומכירות מנויים'!N23 -> 16.2 | C26: ='סיכום אימונים ומכירות מנויים'!N26 -> 3045.6
A27: סה"כ | B27: =SUM(B25:B26) -> 10399.7 | C27: =SUM(C25:C26) -> 9108.1
A31: קבלה | B31: ברוטו עובד | C31: סוציאליות 30% | D31: סה"כ עלות מעביד | E31: עלות חיוב לפרוייקט | H31: אימון סטודיו | I31: סטודיו פיאלטיס | J31: אימונים אישיים | K31: אירועי חברה פילאטיס
A32: 1 | B32: 40 | C32: =B32*1.3 -> 52 | D32: =C32 -> 52 | E32: 70 | H32: 170 | I32: 185 | J32: 150 | K32: 200 | L32: יזם
A33: 1.25 | B33: =$B$32*A33 -> 50 | C33: =B33*1.33 -> 66.5 | D33: =+C33 -> 66.5 | E33: =$E$32*0.25 -> 17.5
A34: 1.5 | B34: =$B$32*A34 -> 60 | C34: =B34*1.33 -> 79.8 | D34: =+C34 -> 79.8 | E34: =$E$32*0.5 -> 35
A35: 1.75 | B35: =$B$32*A35 -> 70 | C35: =B35*1.33 -> 93.1 | D35: =+C35 -> 93.1 | E35: =$E$32*0.75 -> 52.5
A36: 2 | B36: =$B$32*A36 -> 80 | C36: =B36*1.33 -> 106.4 | D36: =+C36 -> 106.4 | E36: =$E$32*1 -> 70
I37: ASDFG
H38: 120 | I38: 140 | L38: עובד בשכר
H39: =H38*1.3 -> 156 | I39: =I38*1.3 -> 182 | L39: עלות מעביד
B46: מס סעיף | C46: שם סעיף | D46: סכום | H46: השוואת שעות עבודה
B47: 181-22636 | C47: עמלות מכירת מנויים פילאטיס | D47: ='סיכום אימונים ומכירות מנויים'!N27 -> 3061.8 | H47: סה"כ שעות עבודה בחילנט | K47: 142
B48: 181-22636 | C48: עמלות מכירת מנויים פילאטיס - חוץ | D48: 0 | H48: שעות עבודה בפועל | K48: ='סיכום אימונים ומכירות מנויים'!C15 -> 55
B49: 181-22620 | C49: שעות עבודה מכירות פילאטיס | D49: =E21+C12 -> 6062.5 | H49: שעות סטודיו פילאטיס מכירות | K49: ='סיכום אימונים ומכירות מנויים'!E15 -> 87
B50: 181-22620 | C50: שעות עבודה מכירות פילאטיס - חוץ | D50: ='סיכום אימונים ומכירות מנויים'!E11*$E$32 -> 0 | H50: שעות אימון אישי לא במשמרת | K50: ='סיכום אימונים ומכירות מנויים'!D13 -> 0
...

Sheet סיכום אימונים ומכירות מנויים
B1: אימונים סטודיו פילאטיס
B2: תוויות שורה | C2: אימונים סטודיו פילאטיס | D2: אימונים אישיים סטודיו פילאטיס | E2: קבלה- מכירות | F2: אירועי חברה | J2: מאמן סטודיו | K2: עלות ממוצע לשיעור
B3: דפנה כץ | C3: 15 | J3: לינוי מזרחי | K3: 120
B4: ליהי כינר | J4: נוי פרוינד צונג | K4: 150
B5: לינוי מזרחי | C5: 12 | J5: רחלי בויים | K5: 120
B6: מורן קליין | J6: נועם שליו | K6: 140
B7: נוי פרוינד צונג | C7: 16 | J7: דפנה כץ | K7: 140
B8: סיוון פריימן | C8: 12 | J8: סיוון פרימן | K8: 160
B9: רחלי בויים | C9: 2 | J9: ספיר הורוביץ | K9: 160
B10: נועם שליו | J10: מורן קליין | K10: 150
B11: סה"כ מאמנים חוץ | C11: =SUM(C3:C10) -> 57 | D11: =SUM(D3:D10) -> 0 | E11: =SUM(E3:E10) -> 0 | F11: =SUM(F3:F10) -> 0 | J11: ממוצע לשיעור | K11: =AVERAGE(K3:K10) -> 142.5
B13: נעמה חיון | C13: 55
B14: ניקול איידלמן | E14: 87
B15: סה"כ שיעורים | C15: =SUM(C13:C14) -> 55 | D15: =SUM(D13:D14) -> 0 | E15: =SUM(E13:E14) -> 87 | F15: =SUM(F13:F14) -> 0
B21: 46204 | C21: פילאטיס
B22: שם המדריך | C22: מנויים חדשים חצי שנתי | D22: עמלת מכירה מנוי | E22: חידוש מנויים /כרטיסייה/אישיים | F22: עמלת חידושים | G22: מנויים חדשים שנתי שנתי | H22: עמלת מכירה | I22: מנויים מזומן שנתי | J22: עמלת מכירה | M22: סה"כ עמלות מכירת - דיווח שכר | N22: סה"כ לחיוב כולל ב.ל 8%
B23: נעמה חיון | D23: 50 | E23: 0.5 | F23: 30 | H23: 70 | M23: =C23*D23+E23*F23+G23*H23+I23*J23 -> 15 | N23: =M23*1.08 -> 16.2
B24: לאון | D24: 50 | F24: 30 | H24: 70 | M24: =C24*D24+E24*F24+G24*H24+I24*J24 -> 0 | N24: =M24*1.08 -> 0
B25: נועם | D25: 50 | F25: 30 | H25: 70 | M25: =C25*D25+E25*F25+G25*H25+I25*J25 -> 0 | N25: =M25*1.08 -> 0
B26: ניקול | C26: 2 | D26: 50 | E26: 21.5 | F26: 30 | G26: 22.5 | H26: 70 | I26: 5 | J26: 100 | M26: =C26*D26+E26*F26+G26*H26+I26*J26 -> 2820 | N26: =M26*1.08 -> 3045.6
B27: סך הכל | E27: =SUM(E23:E26) -> 22 | M27: =SUM(M23:M26) -> 2835 | N27: =SUM(N23:N26) -> 3061.8

Sheet חילנט
B2: מס עובד | C2: שם משפחה | D2: סה"כ לשכר | E2: רגילות 1.00 | F2: שנ 100% | G2: שנ 125% | H2: שנ 150% | I2: אימון אישי (הסכם 680 ) | J2: אימון קבוצתי (הסכם 680 ) | K2: אימון זוגי(הסכם 680 ) | L2: סה"כ שעות פרוייקט
B3: סה"כ חיון נעמה | D3: 55 | E3: 55
B4: סה"כ איידלמן ניקול | D4: 87 | E4: 83.75 | G4: 3.25
B5: סה"כ כללי | D5: =SUM(D3:D4) -> 142 | E5: =SUM(E3:E4) -> 138.75 | F5: =SUM(F3:F4) -> 0 | G5: =SUM(G3:G4) -> 3.25 | H5: =SUM(H3:H4) -> 0 | I5: =SUM(I3:I4) -> 0 | J5: =SUM(J3:J4) -> 0 | K5: =SUM(K3:K4) -> 0 | L5: =SUM(L3:L4) -> 0

Sheet חיוב יזם
D5: חיוב יזם - סטודיו פילאטיס | F5: ='ריכוז שעות'!F5 -> 46174
D8: מס סעיף | E8: שם סעיף | F8: סכום | G8: הערות
D9: ='דוח מרכז לאישור מנהל'!B50 -> 181-22620 | E9: ='דוח מרכז לאישור מנהל'!C50 -> שעות עבודה מכירות פילאטיס - חוץ | F9: ='דוח מרכז לאישור מנהל'!D49 -> 6062.5
D10: ='דוח מרכז לאישור מנהל'!B47 -> 181-22636 | E10: ='דוח מרכז לאישור מנהל'!C47 -> עמלות מכירת מנויים פילאטיס | F10: ='דוח מרכז לאישור מנהל'!D47+'דוח מרכז לאישור מנהל'!D48 -> 3061.8
D11: ='דוח מרכז לאישור מנהל'!B52 -> 181-22604 | E11: ='דוח מרכז לאישור מנהל'!C52 -> שיעורים סטודיו פילאטיס | F11: ='דוח מרכז לאישור מנהל'!D52+'דוח מרכז לאישור מנהל'!D53 -> 20928.5
D12: ='דוח מרכז לאישור מנהל'!B51 -> 181-22601 | E12: ניהול סטודיו פילאטיס | F12: ='דוח מרכז לאישור מנהל'!D51 -> 2000
D13: 181-10109 | E13: השתלמויות | F13: ='דוח מרכז לאישור מנהל'!D56 -> 0
D14: 181-22650 | E14: אימונים אישיים פילאטיס | F14: ='דוח מרכז לאישור מנהל'!D54+'דוח מרכז לאישור מנהל'!D55 -> 0
E15: סה"כ | F15: =SUM(F9:F14) -> 32052.8

Sheet גיליון2
A3: תוויות שורה | B3: ספירה של תאריך
A4: אור-ים זגורי | B4: 8
A5: ברק ביטון | B5: 8
A6: דניאלה גכטמן | B6: 1
A7: זהבה מז'יבובסקי | B7: 18
A8: ליאורה נוריאל | B8: 5
A9: ליאל ויינברגר | B9: 1
A10: ליהי אברמזון | B10: 18
A11: מורן גרינשטיין | B11: 5
A12: ספיר ילינביץ' | B12: 5
A13: עדי סרי | B13: 16
A14: עמית אבן | B14: 2
A15: שמוליק בריל | B15: 1
A16: סכום כולל | B16: 88

Sheet גיליון1
A1: תאריך | B1: יום | C1: שעת התחלה | D1: שעת סיום | E1: סך שעות | F1: סך דקות | G1: סטטוס | H1: מאמן משני | I1: מאמן | J1: אימון | K1: רישומי מתאמנים | L1: אחוז תפוסה | M1: צ'ק אין | N1: רשימת המתנה | O1: סניף
A2: 43466 | B2: שלישי | C2: 0.3125 | D2: 0.34722222 | E2: 0.833 | F2: 50 | G2: מתקיים | H2: אור-ים זגורי | J2: HIIT פונקציונלי | K2: 13 | L2: 86.67 | M2: 12 | N2: 0 | O2: Alon Towers
A3: 43466 | B3: שלישי | C3: 0.77083333 | D3: 0.80555556 | E3: 0.833 | F3: 50 | G3: מתקיים | H3: זהבה מז'יבובסקי | J3: core ומתיחות | K3: 12 | L3: 100 | M3: 8 | N3: 1 | O3: Alon Towers
A4: 43466 | B4: שלישי | C4: 0.35416667 | D4: 0.38888889 | E4: 0.833 | F4: 50 | G4: מתקיים | H4: ליהי אברמזון | J4: יוגה | K4: 12 | L4: 100 | M4: 10 | N4: 5 | O4: Alon Towers
A5: 43466 | B5: שלישי | C5: 0.72916667 | D5: 0.76388889 | E5: 0.833 | F5: 50 | G5: מתקיים | H5: ליאורה נוריאל | J5: Kickbox | K5: 14 | L5: 93.33 | M5: 11 | N5: 0 | O5: Alon Towers
A6: 43467 | B6: רביעי | C6: 0.77083333 | D6: 0.80555556 | E6: 0.833 | F6: 50 | G6: מתקיים | H6: עדי סרי | J6: Alon Skill | K6: 15 | L6: 100 | M6: 11 | N6: 10 | O6: Alon Towers
A7: 43467 | B7: רביעי | C7: 0.3125 | D7: 0.34722222 | E7: 0.833 | F7: 50 | G7: מתקיים | H7: ליאל ויינברגר | J7: יוגה | K7: 12 | L7: 100 | M7: 6 | N7: 0 | O7: Alon Towers
A8: 43467 | B8: רביעי | C8: 0.72916667 | D8: 0.76388889 | E8: 0.833 | F8: 50 | G8: מתקיים | H8: עדי סרי | J8: פילאטיס | K8: 10 | L8: 100 | M8: 8 | N8: 11 | O8: Alon Towers
A9: 43468 | B9: חמישי | C9: 0.35416667 | D9: 0.38888889 | E9: 0.833 | F9: 50 | G9: מתקיים | H9: ספיר ילינביץ' | J9: פילאטיס | K9: 10 | L9: 100 | M9: 8 | N9: 2 | O9: Alon Towers
A10: 43468 | B10: חמישי | C10: 0.72916667 | D10: 0.76388889 | E10: 0.833 | F10: 50 | G10: מתקיים | H10: ליהי אברמזון | J10: Power Yoga | K10: 12 | L10: 100 | M10: 9 | N10: 5 | O10: Alon Towers
A11: 43468 | B11: חמישי | C11: 0.77083333 | D11: 0.80555556 | E11: 0.833 | F11: 50 | G11: מתקיים | H11: ברק ביטון | J11: Ouotdoor Functional | K11: 20 | L11: 100 | M11: 18 | N11: 0 | O11: Alon Towers
A12: 43468 | B12: חמישי | C12: 0.3125 | D12: 0.34722222 | E12: 0.833 | F12: 50 | G12: מתקיים | H12: זהבה מז'יבובסקי | J12: HIIT TRX | K12: 11 | L12: 78.57 | M12: 9 | N12: 0 | O12: Alon Towers
A13: 43471 | B13: ראשון | C13: 0.35416667 | D13: 0.38888889 | E13: 0.833 | F13: 50 | G13: מתקיים | H13: ליהי אברמזון | J13: יוגה | K13: 12 | L13: 100 | M13: 12 | N13: 5 | O13: Alon Towers
... A89: 43496 | B89: חמישי | C89: 0.35416667 | D89: 0.38888889 | E89: 0.833 | F89: 50 | G89: מתקיים | H89: ספיר ילינביץ' | J89: פילאטיס | K89: 11 | L89: 91.67 | M89: 10 | N89: 1 | O89: Alon Towers

Sheet חגים
A1: תאריך | B1: תיאור אירוע | C1: סוג אירוע
A2: 39721 | B2: ראש השנה א' | C2: חגים דתיים
A3: 39722 | B3: ראש השנה ב' | C3: חגים דתיים
A4: 39723 | B4: צום גדליה | C4: חגים דתיים
A5: 39729 | B5: ערב יום כיפור | C5: חגים דתיים
A6: 39730 | B6: יום כיפור | C6: חגים דתיים
A7: 39734 | B7: ערב סוכות | C7: חגים דתיים
A8: 39735 | B8: סוכות | C8: חגים דתיים
A9: 39736 | B9: חול המועד סוכות (1) | C9: חגים דתיים
A10: 39737 | B10: חול המועד סוכות (2) | C10: חגים דתיים
A11: 39738 | B11: חול המועד סוכות (3) | C11: חגים דתיים
A12: 39739 | B12: חול המועד סוכות (4) | C12: חגים דתיים
A13: 39740 | B13: חול המועד סוכות (5) | C13: חגים דתיים
... A794: 46795 | B794: ט"ו בשבט | C794: חגים דתיים

Sheet דוח אימוני סטודיו
A1: תאריך | B1: יום | C1: שעת התחלה | D1: שעת סיום | E1: סך שעות | F1: סך דקות | G1: סטטוס | H1: מאמן משני | I1: מאמן | J1: אימון | K1: רישומי מתאמנים | L1: צ'ק אין | M1: רשימת המתנה | N1: סניף
A2: 43405 | B2: חמישי | C2: 0.33333333 | D2: 0.36805556 | E2: 0.833 | F2: 50 | G2: מתקיים | H2: זהבה מז'יבובסקי | J2: HIIT TRX | K2: 7 | L2: 7 | M2: 17 | N2: Alon Towers
A3: 43405 | B3: חמישי | C3: 0.75 | D3: 0.78472222 | E3: 0.833 | F3: 50 | G3: מתקיים | J3: יוגה | K3: 10 | L3: 6 | M3: 31 | N3: Alon Towers
A4: 43408 | B4: ראשון | C4: 0.35416667 | D4: 0.38888889 | E4: 0.833 | F4: 50 | G4: מתקיים | J4: יוגה | K4: 10 | L4: 0 | M4: 6 | N4: Alon Towers | P4: ספירה של תאריך | Q4: תוויות עמודה
A5: 43408 | B5: ראשון | C5: 0.75 | D5: 0.78472222 | E5: 0.833 | F5: 50 | G5: מתקיים | H5: עדי סרי | J5: ALON SKILL | K5: 12 | L5: 11 | M5: 0 | N5: Alon Towers | P5: תוויות שורה | Q5: השיעור בוטל | R5: מתקיים | S5: סכום כולל
A6: 43408 | B6: ראשון | C6: 0.79166667 | D6: 0.82638889 | E6: 0.833 | F6: 50 | G6: מתקיים | H6: ברק ביטון | J6: HIIT TRX | K6: 9 | L6: 9 | M6: 0 | N6: Alon Towers | R6: 3 | S6: 3
A7: 43409 | B7: שני | C7: 0.3125 | D7: 0.34722222 | E7: 0.833 | F7: 50 | G7: מתקיים | H7: עדי סרי | J7: פילאטיס | K7: 9 | L7: 8 | M7: 0 | N7: Alon Towers | P7: אור-ים זגורי | R7: 4 | S7: 4
A8: 43409 | B8: שני | C8: 0.35416667 | D8: 0.38888889 | E8: 0.833 | F8: 50 | G8: מתקיים | H8: רועי עתריה | J8: HIIT פונקציונלי | K8: 10 | L8: 9 | M8: 0 | N8: Alon Towers | P8: ברק ביטון | R8: 7 | S8: 7
A9: 43409 | B9: שני | C9: 0.79166667 | D9: 0.82638889 | E9: 0.833 | F9: 50 | G9: מתקיים | J9: יוגה | K9: 10 | L9: 8 | M9: 6 | N9: Alon Towers | P9: גיל בקמן | R9: 9 | S9: 9
A10: 43410 | B10: שלישי | C10: 0.75 | D10: 0.78472222 | E10: 0.833 | F10: 50 | G10: מתקיים | H10: מורן גרינשטיין | J10: HIIT פונקציונלי | K10: 12 | L10: 9 | M10: 0 | N10: Alon Towers | P10: זהבה מז'יבובסקי | Q10: 1 | R10: 9 | S10: 10
A11: 43410 | B11: שלישי | C11: 0.3125 | D11: 0.34722222 | E11: 0.833 | F11: 50 | G11: מתקיים | H11: גיל בקמן | J11: יוגה | K11: 5 | L11: 3 | M11: 0 | N11: Alon Towers | P11: ליהי אברמזון | R11: 7 | S11: 7
A12: 43410 | B12: שלישי | C12: 0.35416667 | D12: 0.38888889 | E12: 0.833 | F12: 50 | G12: מתקיים | H12: אור-ים זגורי | J12: HIIT TRX | K12: 6 | L12: 4 | M12: 0 | N12: Alon Towers | P12: מורן גרינשטיין | R12: 4 | S12: 4
A13: 43411 | B13: רביעי | C13: 0.75 | D13: 0.78472222 | E13: 0.833 | F13: 50 | G13: מתקיים | H13: עדי סרי | J13: פילאטיס | K13: 10 | L13: 9 | M13: 12 | N13: Alon Towers | P13: מתן הלוי | R13: 2 | S13: 2
A14: 43411 | B14: רביעי | C14: 0.3125 | D14: 0.34722222 | E14: 0.833 | F14: 50 | G14: מתקיים | H14: זהבה מז'יבובסקי | J14: HIIT פונקציונלי | K14: 11 | L14: 8 | M14: 0 | N14: Alon Towers | P14: עדי סרי | R14: 19 | S14: 19
A15: 43411 | B15: רביעי | C15: 0.79166667 | D15: 0.82638889 | E15: 0.833 | F15: 50 | G15: מתקיים | H15: עדי סרי | J15: ALON SKILL | K15: 14 | L15: 12 | M15: 0 | N15: Alon Towers | P15: רועי עתריה | Q15: 1 | R15: 3 | S15: 4
A16: 43412 | B16: חמישי | C16: 0.35416667 | D16: 0.38888889 | E16: 0.833 | F16: 50 | G16: מתקיים | H16: זהבה מז'יבובסקי | J16: ALON SKILL | K16: 12 | L16: 12 | M16: 0 | N16: Alon Towers | P16: סכום כולל | Q16: 2 | R16: 67 | S16: 69
A17: 43412 | B17: חמישי | C17: 0.75 | D17: 0.78472222 | E17: 0.833 | F17: 50 | G17: מתקיים | H17: ליהי אברמזון | J17: יוגה | K17: 11 | L17: 8 | M17: 16 | N17: Alon Towers
A18: 43412 | B18: חמישי | C18: 0.79166667 | D18: 0.82638889 | E18: 0.833 | F18: 50 | G18: מתקיים | H18: ברק ביטון | J18: OUTDOOR FUNCTIONAL | K18: 10 | L18: 7 | M18: 0 | N18: Alon Towers
A19: 43415 | B19: ראשון | C19: 0.3125 | D19: 0.34722222 | E19: 0.833 | F19: 50 | G19: מתקיים | H19: ליהי אברמזון | J19: יוגה | K19: 10 | L19: 10 | M19: 0 | N19: Alon Towers
A20: 43415 | B20: ראשון | C20: 0.75 | D20: 0.78472222 | E20: 0.833 | F20: 50 | G20: מתקיים | H20: מתן הלוי | J20: KICK AND SHAPE | K20: 10 | L20: 10 | M20: 0 | N20: Alon Towers
A21: 43415 | B21: ראשון | C21: 0.79166667 | D21: 0.82638889 | E21: 0.833 | F21: 50 | G21: מתקיים | H21: עדי סרי | J21: פילאטיס | K21: 9 | L21: 8 | M21: 0 | N21: Alon Towers
A22: 43416 | B22: שני | C22: 0.3125 | D22: 0.34722222 | E22: 0.833 | F22: 50 | G22: מתקיים | H22: עדי סרי | J22: פילאטיס | K22: 10 | L22: 9 | M22: 0 | N22: Alon Towers
A23: 43416 | B23: שני | C23: 0.35416667 | D23: 0.38888889 | E23: 0.833 | F23: 50 | G23: מתקיים | H23: עדי סרי | J23: ALON SKILL | K23: 11 | L23: 10 | M23: 0 | N23: Alon Towers
A24: 43416 | B24: שני | C24: 0.75 | D24: 0.78472222 | E24: 0.833 | F24: 50 | G24: מתקיים | H24: מורן גרינשטיין | J24: HIIT TRX | K24: 7 | L24: 7 | M24: 0 | N24: Alon Towers
A25: 43416 | B25: שני | C25: 0.79166667 | D25: 0.82638889 | E25: 0.833 | F25: 50 | G25: מתקיים | H25: ליהי אברמזון | J25: יוגה | K25: 10 | L25: 8 | M25: 10 | N25: Alon Towers
A26: 43417 | B26: שלישי | C26: 0.35416667 | D26: 0.38888889 | E26: 0.833 | F26: 50 | G26: מתקיים | H26: רועי עתריה | J26: HIIT פונקציונלי | K26: 6 | L26: 5 | M26: 0 | N26: Alon Towers
A27: 43417 | B27: שלישי | C27: 0.75 | D27: 0.78472222 | E27: 0.833 | F27: 50 | G27: מתקיים | H27: ברק ביטון | J27: OUTDOOR FUNCTIONAL | K27: 12 | L27: 10 | M27: 0 | N27: Alon Towers
A28: 43417 | B28: שלישי | C28: 0.79166667 | D28: 0.82638889 | E28: 0.833 | F28: 50 | G28: השיעור בוטל | H28: זהבה מז'יבובסקי | J28: ALON SKILL | K28: 0 | L28: 0 | M28: 0 | N28: Alon Towers
... A70: 43433 | B70: חמישי | C70: 0.3125 | D70: 0.34722222 | E70: 0.833 | F70: 50 | G70: מתקיים | H70: זהבה מז'יבובסקי | J70: core ומתיחות | K70: 10 | L70: 6 | M70: 0 | N70: Alon Towers
