Workbook

Sheet ריכוז שעות
E1: אריאל ספא בע"מ
E2: A+ סטריט מול בע"מ
A3: שעות פעילות חד"כ | B3: 0.91666667 | C3: 0.29166667
D5: נוכחות | E5: יולי | F5: 46204
A7: יום | B7: יום | C7: חג | D7: משמרת בוקר | E7: משמרת ערב ארוכה | F7: משמרת ערב סגירה | G7: סה"כ
A8: בחודש | B8: בשבוע | C8: וימים מיוחדים | G8: שעות עבודה | H8: הערות
A9: 46143 | B9: =TEXT(A9,"dddd") -> Friday | C9: =VLOOKUP(A9,חגים!A2:B794,2,FALSE) -> #N/A | D9: =IF(OR(B9=$N$26),$N$18,IF(OR(B9=$N$27),$N$19,IF(OR(B9=$N$21,B9=$N$22,B9=$N$23,B9=$N$24,B9=$N$25),$N$17,"ERR"))) -> ERR | E9: =IF(OR(B9=$N$26),$O$18,IF(OR(B9=$N$27),$O$19,IF(OR(B9=$N$21,B9=$N$22,B9=$N$23,B9=$N$24,B9=$N$25),$O$17,"ERR"))) -> ERR | F9: =IF(OR(B9=$N$26,B9=$N$27),"CLOSED",IF(OR(B9=$N$21,B9=$N$22,B9=$N$23,B9=$N$24,B9=$N$25),$P$17,"ERR")) -> ERR | G9: =IF(OR(B9=$N$26),$O$26,IF(OR(B9=$N$27),$O$27,IF(OR(B9=$N$21,B9=$N$22,B9=$N$23,B9=$N$24,B9=$N$25),$O$21,"ERR"))) -> ERR
A10: 46144 | B10: =TEXT(A10,"dddd") -> Saturday | C10: =VLOOKUP(A10,[1]חגים!$A$2:$C$794,2,FALSE) -> #N/A | D10: =IF(OR(B10=$N$26),$N$18,IF(OR(B10=$N$27),$N$19,IF(OR(B10=$N$21,B10=$N$22,B10=$N$23,B10=$N$24,B10=$N$25),$N$17,"ERR"))) -> ERR | E10: =IF(OR(B10=$N$26),$O$18,IF(OR(B10=$N$27),$O$19,IF(OR(B10=$N$21,B10=$N$22,B10=$N$23,B10=$N$24,B10=$N$25),$O$17,"ERR"))) -> ERR | F10: =IF(OR(B10=$N$26,B10=$N$27),"CLOSED",IF(OR(B10=$N$21,B10=$N$22,B10=$N$23,B10=$N$24,B10=$N$25),$P$17,"ERR")) -> ERR | G10: =IF(OR(B10=$N$26),$O$26,IF(OR(B10=$N$27),$O$27,IF(OR(B10=$N$21,B10=$N$22,B10=$N$23,B10=$N$24,B10=$N$25),$O$21,"ERR"))) -> ERR
A11: 46145 | B11: =TEXT(A11,"dddd") -> Sunday | C11: =VLOOKUP(A11,[1]חגים!$A$2:$C$794,2,FALSE) -> #N/A | D11: =IF(OR(B11=$N$26),$N$18,IF(OR(B11=$N$27),$N$19,IF(OR(B11=$N$21,B11=$N$22,B11=$N$23,B11=$N$24,B11=$N$25),$N$17,"ERR"))) -> ERR | E11: =IF(OR(B11=$N$26),$O$18,IF(OR(B11=$N$27),$O$19,IF(OR(B11=$N$21,B11=$N$22,B11=$N$23,B11=$N$24,B11=$N$25),$O$17,"ERR"))) -> ERR | F11: =IF(OR(B11=$N$26,B11=$N$27),"CLOSED",IF(OR(B11=$N$21,B11=$N$22,B11=$N$23,B11=$N$24,B11=$N$25),$P$17,"ERR")) -> ERR | G11: =IF(OR(B11=$N$26),$O$26,IF(OR(B11=$N$27),$O$27,IF(OR(B11=$N$21,B11=$N$22,B11=$N$23,B11=$N$24,B11=$N$25),$O$21,"ERR"))) -> ERR
A12: 46146 | B12: =TEXT(A12,"dddd") -> Monday | C12: =VLOOKUP(A12,[1]חגים!$A$2:$C$794,2,FALSE) -> #N/A | D12: =IF(OR(B12=$N$26),$N$18,IF(OR(B12=$N$27),$N$19,IF(OR(B12=$N$21,B12=$N$22,B12=$N$23,B12=$N$24,B12=$N$25),$N$17,"ERR"))) -> ERR | E12: =IF(OR(B12=$N$26),$O$18,IF(OR(B12=$N$27),$O$19,IF(OR(B12=$N$21,B12=$N$22,B12=$N$23,B12=$N$24,B12=$N$25),$O$17,"ERR"))) -> ERR | F12: =IF(OR(B12=$N$26,B12=$N$27),"CLOSED",IF(OR(B12=$N$21,B12=$N$22,B12=$N$23,B12=$N$24,B12=$N$25),$P$17,"ERR")) -> ERR | G12: =IF(OR(B12=$N$26),$O$26,IF(OR(B12=$N$27),$O$27,IF(OR(B12=$N$21,B12=$N$22,B12=$N$23,B12=$N$24,B12=$N$25),$O$21,"ERR"))) -> ERR
A13: 46147 | B13: =TEXT(A13,"dddd") -> Tuesday | C13: =VLOOKUP(A13,[1]חגים!$A$2:$C$794,2,FALSE) -> #N/A | D13: =IF(OR(B13=$N$26),$N$18,IF(OR(B13=$N$27),$N$19,IF(OR(B13=$N$21,B13=$N$22,B13=$N$23,B13=$N$24,B13=$N$25),$N$17,"ERR"))) -> ERR | E13: =IF(OR(B13=$N$26),$O$18,IF(OR(B13=$N$27),$O$19,IF(OR(B13=$N$21,B13=$N$22,B13=$N$23,B13=$N$24,B13=$N$25),$O$17,"ERR"))) -> ERR | F13: =IF(OR(B13=$N$26,B13=$N$27),"CLOSED",IF(OR(B13=$N$21,B13=$N$22,B13=$N$23,B13=$N$24,B13=$N$25),$P$17,"ERR")) -> ERR | G13: =IF(OR(B13=$N$26),$O$26,IF(OR(B13=$N$27),$O$27,IF(OR(B13=$N$21,B13=$N$22,B13=$N$23,B13=$N$24,B13=$N$25),$O$21,"ERR"))) -> ERR
A14: 46148 | B14: =TEXT(A14,"dddd") -> Wednesday | C14: =VLOOKUP(A14,[1]חגים!$A$2:$C$794,2,FALSE) -> #N/A | D14: =IF(OR(B14=$N$26),$N$18,IF(OR(B14=$N$27),$N$19,IF(OR(B14=$N$21,B14=$N$22,B14=$N$23,B14=$N$24,B14=$N$25),$N$17,"ERR"))) -> ERR | E14: =IF(OR(B14=$N$26),$O$18,IF(OR(B14=$N$27),$O$19,IF(OR(B14=$N$21,B14=$N$22,B14=$N$23,B14=$N$24,B14=$N$25),$O$17,"ERR"))) -> ERR | F14: =IF(OR(B14=$N$26,B14=$N$27),"CLOSED",IF(OR(B14=$N$21,B14=$N$22,B14=$N$23,B14=$N$24,B14=$N$25),$P$17,"ERR")) -> ERR | G14: =IF(OR(B14=$N$26),$O$26,IF(OR(B14=$N$27),$O$27,IF(OR(B14=$N$21,B14=$N$22,B14=$N$23,B14=$N$24,B14=$N$25),$O$21,"ERR"))) -> ERR
A15: 46149 | B15: =TEXT(A15,"dddd") -> Thursday | C15: =VLOOKUP(A15,[1]חגים!$A$2:$C$794,2,FALSE) -> #N/A | D15: =IF(OR(B15=$N$26),$N$18,IF(OR(B15=$N$27),$N$19,IF(OR(B15=$N$21,B15=$N$22,B15=$N$23,B15=$N$24,B15=$N$25),$N$17,"ERR"))) -> ERR | E15: =IF(OR(B15=$N$26),$O$18,IF(OR(B15=$N$27),$O$19,IF(OR(B15=$N$21,B15=$N$22,B15=$N$23,B15=$N$24,B15=$N$25),$O$17,"ERR"))) -> ERR | F15: =IF(OR(B15=$N$26,B15=$N$27),"CLOSED",IF(OR(B15=$N$21,B15=$N$22,B15=$N$23,B15=$N$24,B15=$N$25),$P$17,"ERR")) -> ERR | G15: =IF(OR(B15=$N$26),$O$26,IF(OR(B15=$N$27),$O$27,IF(OR(B15=$N$21,B15=$N$22,B15=$N$23,B15=$N$24,B15=$N$25),$O$21,"ERR"))) -> ERR
A16: 46150 | B16: =TEXT(A16,"dddd") -> Friday | C16: =VLOOKUP(A16,[1]חגים!$A$2:$C$794,2,FALSE) -> #N/A | D16: =IF(OR(B16=$N$26),$N$18,IF(OR(B16=$N$27),$N$19,IF(OR(B16=$N$21,B16=$N$22,B16=$N$23,B16=$N$24,B16=$N$25),$N$17,"ERR"))) -> ERR | E16: =IF(OR(B16=$N$26),$O$18,IF(OR(B16=$N$27),$O$19,IF(OR(B16=$N$21,B16=$N$22,B16=$N$23,B16=$N$24,B16=$N$25),$O$17,"ERR"))) -> ERR | F16: =IF(OR(B16=$N$26,B16=$N$27),"CLOSED",IF(OR(B16=$N$21,B16=$N$22,B16=$N$23,B16=$N$24,B16=$N$25),$P$17,"ERR")) -> ERR | G16: =IF(OR(B16=$N$26),$O$26,IF(OR(B16=$N$27),$O$27,IF(OR(B16=$N$21,B16=$N$22,B16=$N$23,B16=$N$24,B16=$N$25),$O$21,"ERR"))) -> ERR | N16: בוקר | O16: ערב | P16: סגירה
A17: 46151 | B17: =TEXT(A17,"dddd") -> Saturday | C17: =VLOOKUP(A17,[1]חגים!$A$2:$C$794,2,FALSE) -> #N/A | D17: =IF(OR(B17=$N$26),$N$18,IF(OR(B17=$N$27),$N$19,IF(OR(B17=$N$21,B17=$N$22,B17=$N$23,B17=$N$24,B17=$N$25),$N$17,"ERR"))) -> ERR | E17: =IF(OR(B17=$N$26),$O$18,IF(OR(B17=$N$27),$O$19,IF(OR(B17=$N$21,B17=$N$22,B17=$N$23,B17=$N$24,B17=$N$25),$O$17,"ERR"))) -> ERR | F17: =IF(OR(B17=$N$26,B17=$N$27),"CLOSED",IF(OR(B17=$N$21,B17=$N$22,B17=$N$23,B17=$N$24,B17=$N$25),$P$17,"ERR")) -> ERR | G17: =IF(OR(B17=$N$26),$O$26,IF(OR(B17=$N$27),$O$27,IF(OR(B17=$N$21,B17=$N$22,B17=$N$23,B17=$N$24,B17=$N$25),$O$21,"ERR"))) -> ERR | L17: ראשון - חמישי | N17: 07:00-11:45 | O17: 12:00-16:45 | P17: 17:00-22:00
A18: 46152 | B18: =TEXT(A18,"dddd") -> Sunday | C18: =VLOOKUP(A18,[1]חגים!$A$2:$C$794,2,FALSE) -> #N/A | D18: =IF(OR(B18=$N$26),$N$18,IF(OR(B18=$N$27),$N$19,IF(OR(B18=$N$21,B18=$N$22,B18=$N$23,B18=$N$24,B18=$N$25),$N$17,"ERR"))) -> ERR | E18: =IF(OR(B18=$N$26),$O$18,IF(OR(B18=$N$27),$O$19,IF(OR(B18=$N$21,B18=$N$22,B18=$N$23,B18=$N$24,B18=$N$25),$O$17,"ERR"))) -> ERR | F18: =IF(OR(B18=$N$26,B18=$N$27),"CLOSED",IF(OR(B18=$N$21,B18=$N$22,B18=$N$23,B18=$N$24,B18=$N$25),$P$17,"ERR")) -> ERR | G18: =IF(OR(B18=$N$26),$O$26,IF(OR(B18=$N$27),$O$27,IF(OR(B18=$N$21,B18=$N$22,B18=$N$23,B18=$N$24,B18=$N$25),$O$21,"ERR"))) -> ERR | L18: שישי | N18: 07:00-14:00
A19: 46153 | B19: =TEXT(A19,"dddd") -> Monday | C19: =VLOOKUP(A19,[1]חגים!$A$2:$C$794,2,FALSE) -> #N/A | D19: =IF(OR(B19=$N$26),$N$18,IF(OR(B19=$N$27),$N$19,IF(OR(B19=$N$21,B19=$N$22,B19=$N$23,B19=$N$24,B19=$N$25),$N$17,"ERR"))) -> ERR | E19: =IF(OR(B19=$N$26),$O$18,IF(OR(B19=$N$27),$O$19,IF(OR(B19=$N$21,B19=$N$22,B19=$N$23,B19=$N$24,B19=$N$25),$O$17,"ERR"))) -> ERR | F19: =IF(OR(B19=$N$26,B19=$N$27),"CLOSED",IF(OR(B19=$N$21,B19=$N$22,B19=$N$23,B19=$N$24,B19=$N$25),$P$17,"ERR")) -> ERR | G19: =IF(OR(B19=$N$26),$O$26,IF(OR(B19=$N$27),$O$27,IF(OR(B19=$N$21,B19=$N$22,B19=$N$23,B19=$N$24,B19=$N$25),$O$21,"ERR"))) -> ERR | L19: שבת | O19: 16:00-20:00
A20: 46154 | B20: =TEXT(A20,"dddd") -> Tuesday | C20: =VLOOKUP(A20,[1]חגים!$A$2:$C$794,2,FALSE) -> #N/A | D20: =IF(OR(B20=$N$26),$N$18,IF(OR(B20=$N$27),$N$19,IF(OR(B20=$N$21,B20=$N$22,B20=$N$23,B20=$N$24,B20=$N$25),$N$17,"ERR"))) -> ERR | E20: =IF(OR(B20=$N$26),$O$18,IF(OR(B20=$N$27),$O$19,IF(OR(B20=$N$21,B20=$N$22,B20=$N$23,B20=$N$24,B20=$N$25),$O$17,"ERR"))) -> ERR | F20: =IF(OR(B20=$N$26,B20=$N$27),"CLOSED",IF(OR(B20=$N$21,B20=$N$22,B20=$N$23,B20=$N$24,B20=$N$25),$P$17,"ERR")) -> ERR | G20: =IF(OR(B20=$N$26),$O$26,IF(OR(B20=$N$27),$O$27,IF(OR(B20=$N$21,B20=$N$22,B20=$N$23,B20=$N$24,B20=$N$25),$O$21,"ERR"))) -> ERR
A21: 46155 | B21: =TEXT(A21,"dddd") -> Wednesday | C21: =VLOOKUP(A21,[1]חגים!$A$2:$C$794,2,FALSE) -> #N/A | D21: =IF(OR(B21=$N$26),$N$18,IF(OR(B21=$N$27),$N$19,IF(OR(B21=$N$21,B21=$N$22,B21=$N$23,B21=$N$24,B21=$N$25),$N$17,"ERR"))) -> ERR | E21: =IF(OR(B21=$N$26),$O$18,IF(OR(B21=$N$27),$O$19,IF(OR(B21=$N$21,B21=$N$22,B21=$N$23,B21=$N$24,B21=$N$25),$O$17,"ERR"))) -> ERR | F21: =IF(OR(B21=$N$26,B21=$N$27),"CLOSED",IF(OR(B21=$N$21,B21=$N$22,B21=$N$23,B21=$N$24,B21=$N$25),$P$17,"ERR")) -> ERR | G21: =IF(OR(B21=$N$26),$O$26,IF(OR(B21=$N$27),$O$27,IF(OR(B21=$N$21,B21=$N$22,B21=$N$23,B21=$N$24,B21=$N$25),$O$21,"ERR"))) -> ERR | N21: יום ראשון | O21: 18.5
A22: 46156 | B22: =TEXT(A22,"dddd") -> Thursday | C22: =VLOOKUP(A22,[1]חגים!$A$2:$C$794,2,FALSE) -> #N/A | D22: =IF(OR(B22=$N$26),$N$18,IF(OR(B22=$N$27),$N$19,IF(OR(B22=$N$21,B22=$N$22,B22=$N$23,B22=$N$24,B22=$N$25),$N$17,"ERR"))) -> ERR | E22: =IF(OR(B22=$N$26),$O$18,IF(OR(B22=$N$27),$O$19,IF(OR(B22=$N$21,B22=$N$22,B22=$N$23,B22=$N$24,B22=$N$25),$O$17,"ERR"))) -> ERR | F22: =IF(OR(B22=$N$26,B22=$N$27),"CLOSED",IF(OR(B22=$N$21,B22=$N$22,B22=$N$23,B22=$N$24,B22=$N$25),$P$17,"ERR")) -> ERR | G22: =IF(OR(B22=$N$26),$O$26,IF(OR(B22=$N$27),$O$27,IF(OR(B22=$N$21,B22=$N$22,B22=$N$23,B22=$N$24,B22=$N$25),$O$21,"ERR"))) -> ERR | N22: יום שני | O22: 0 | Q22: ינואר | R22: נורמאטיבי
A23: 46157 | B23: =TEXT(A23,"dddd") -> Friday | C23: =VLOOKUP(A23,[1]חגים!$A$2:$C$794,2,FALSE) -> #N/A | D23: =IF(OR(B23=$N$26),$N$18,IF(OR(B23=$N$27),$N$19,IF(OR(B23=$N$21,B23=$N$22,B23=$N$23,B23=$N$24,B23=$N$25),$N$17,"ERR"))) -> ERR | E23: =IF(OR(B23=$N$26),$O$18,IF(OR(B23=$N$27),$O$19,IF(OR(B23=$N$21,B23=$N$22,B23=$N$23,B23=$N$24,B23=$N$25),$O$17,"ERR"))) -> ERR | F23: =IF(OR(B23=$N$26,B23=$N$27),"CLOSED",IF(OR(B23=$N$21,B23=$N$22,B23=$N$23,B23=$N$24,B23=$N$25),$P$17,"ERR")) -> ERR | G23: =IF(OR(B23=$N$26),$O$26,IF(OR(B23=$N$27),$O$27,IF(OR(B23=$N$21,B23=$N$22,B23=$N$23,B23=$N$24,B23=$N$25),$O$21,"ERR"))) -> ERR | N23: יום שלישי | R23: שעות | S23: מס' שעות | T23: מס' עובדים
A24: 46158 | B24: =TEXT(A24,"dddd") -> Saturday | C24: =VLOOKUP(A24,[1]חגים!$A$2:$C$794,2,FALSE) -> #N/A | D24: =IF(OR(B24=$N$26),$N$18,IF(OR(B24=$N$27),$N$19,IF(OR(B24=$N$21,B24=$N$22,B24=$N$23,B24=$N$24,B24=$N$25),$N$17,"ERR"))) -> ERR | E24: =IF(OR(B24=$N$26),$O$18,IF(OR(B24=$N$27),$O$19,IF(OR(B24=$N$21,B24=$N$22,B24=$N$23,B24=$N$24,B24=$N$25),$O$17,"ERR"))) -> ERR | F24: =IF(OR(B24=$N$26,B24=$N$27),"CLOSED",IF(OR(B24=$N$21,B24=$N$22,B24=$N$23,B24=$N$24,B24=$N$25),$P$17,"ERR")) -> ERR | G24: =IF(OR(B24=$N$26),$O$26,IF(OR(B24=$N$27),$O$27,IF(OR(B24=$N$21,B24=$N$22,B24=$N$23,B24=$N$24,B24=$N$25),$O$21,"ERR"))) -> ERR | N24: יום רביעי | Q24: ראשון - חמישי | R24: 07:00-11:45 | S24: 4.75 | T24: 1
A25: 46159 | B25: =TEXT(A25,"dddd") -> Sunday | C25: =VLOOKUP(A25,[1]חגים!$A$2:$C$794,2,FALSE) -> #N/A | D25: =IF(OR(B25=$N$26),$N$18,IF(OR(B25=$N$27),$N$19,IF(OR(B25=$N$21,B25=$N$22,B25=$N$23,B25=$N$24,B25=$N$25),$N$17,"ERR"))) -> ERR | E25: =IF(OR(B25=$N$26),$O$18,IF(OR(B25=$N$27),$O$19,IF(OR(B25=$N$21,B25=$N$22,B25=$N$23,B25=$N$24,B25=$N$25),$O$17,"ERR"))) -> ERR | F25: =IF(OR(B25=$N$26,B25=$N$27),"CLOSED",IF(OR(B25=$N$21,B25=$N$22,B25=$N$23,B25=$N$24,B25=$N$25),$P$17,"ERR")) -> ERR | G25: =IF(OR(B25=$N$26),$O$26,IF(OR(B25=$N$27),$O$27,IF(OR(B25=$N$21,B25=$N$22,B25=$N$23,B25=$N$24,B25=$N$25),$O$21,"ERR"))) -> ERR | N25: יום חמישי | R25: 12:00-16:45 | S25: 4.75 | T25: 1
A26: 46160 | B26: =TEXT(A26,"dddd") -> Monday | C26: =VLOOKUP(A26,[1]חגים!$A$2:$C$794,2,FALSE) -> #N/A | D26: =IF(OR(B26=$N$26),$N$18,IF(OR(B26=$N$27),$N$19,IF(OR(B26=$N$21,B26=$N$22,B26=$N$23,B26=$N$24,B26=$N$25),$N$17,"ERR"))) -> ERR | E26: =IF(OR(B26=$N$26),$O$18,IF(OR(B26=$N$27),$O$19,IF(OR(B26=$N$21,B26=$N$22,B26=$N$23,B26=$N$24,B26=$N$25),$O$17,"ERR"))) -> ERR | F26: =IF(OR(B26=$N$26,B26=$N$27),"CLOSED",IF(OR(B26=$N$21,B26=$N$22,B26=$N$23,B26=$N$24,B26=$N$25),$P$17,"ERR")) -> ERR | G26: =IF(OR(B26=$N$26),$O$26,IF(OR(B26=$N$27),$O$27,IF(OR(B26=$N$21,B26=$N$22,B26=$N$23,B26=$N$24,B26=$N$25),$O$21,"ERR"))) -> ERR | N26: יום שישי | O26: 7.5 | R26: 17:00-22:00 | S26: 5 | T26: 1
A27: 46161 | B27: =TEXT(A27,"dddd") -> Tuesday | C27: =VLOOKUP(A27,[1]חגים!$A$2:$C$794,2,FALSE) -> #N/A | D27: =IF(OR(B27=$N$26),$N$18,IF(OR(B27=$N$27),$N$19,IF(OR(B27=$N$21,B27=$N$22,B27=$N$23,B27=$N$24,B27=$N$25),$N$17,"ERR"))) -> ERR | E27: =IF(OR(B27=$N$26),$O$18,IF(OR(B27=$N$27),$O$19,IF(OR(B27=$N$21,B27=$N$22,B27=$N$23,B27=$N$24,B27=$N$25),$O$17,"ERR"))) -> ERR | F27: =IF(OR(B27=$N$26,B27=$N$27),"CLOSED",IF(OR(B27=$N$21,B27=$N$22,B27=$N$23,B27=$N$24,B27=$N$25),$P$17,"ERR")) -> ERR | G27: =IF(OR(B27=$N$26),$O$26,IF(OR(B27=$N$27),$O$27,IF(OR(B27=$N$21,B27=$N$22,B27=$N$23,B27=$N$24,B27=$N$25),$O$21,"ERR"))) -> ERR | N27: שבת | O27: 4 | Q27: שישי | R27: 07:00-14:00 | S27: 7 | T27: 1
A28: 46162 | B28: =TEXT(A28,"dddd") -> Wednesday | C28: =VLOOKUP(A28,[1]חגים!$A$2:$C$794,2,FALSE) -> #N/A | D28: =IF(OR(B28=$N$26),$N$18,IF(OR(B28=$N$27),$N$19,IF(OR(B28=$N$21,B28=$N$22,B28=$N$23,B28=$N$24,B28=$N$25),$N$17,"ERR"))) -> ERR | E28: =IF(OR(B28=$N$26),$O$18,IF(OR(B28=$N$27),$O$19,IF(OR(B28=$N$21,B28=$N$22,B28=$N$23,B28=$N$24,B28=$N$25),$O$17,"ERR"))) -> ERR | F28: =IF(OR(B28=$N$26,B28=$N$27),"CLOSED",IF(OR(B28=$N$21,B28=$N$22,B28=$N$23,B28=$N$24,B28=$N$25),$P$17,"ERR")) -> ERR | G28: =IF(OR(B28=$N$26),$O$26,IF(OR(B28=$N$27),$O$27,IF(OR(B28=$N$21,B28=$N$22,B28=$N$23,B28=$N$24,B28=$N$25),$O$21,"ERR"))) -> ERR
A29: 46163 | B29: =TEXT(A29,"dddd") -> Thursday | C29: =VLOOKUP(A29,[1]חגים!$A$2:$C$794,2,FALSE) -> #N/A | D29: =IF(OR(B29=$N$26),$N$18,IF(OR(B29=$N$27),$N$19,IF(OR(B29=$N$21,B29=$N$22,B29=$N$23,B29=$N$24,B29=$N$25),$N$17,"ERR"))) -> ERR | E29: =IF(OR(B29=$N$26),$O$18,IF(OR(B29=$N$27),$O$19,IF(OR(B29=$N$21,B29=$N$22,B29=$N$23,B29=$N$24,B29=$N$25),$O$17,"ERR"))) -> ERR | F29: =IF(OR(B29=$N$26,B29=$N$27),"CLOSED",IF(OR(B29=$N$21,B29=$N$22,B29=$N$23,B29=$N$24,B29=$N$25),$P$17,"ERR")) -> ERR | G29: =IF(OR(B29=$N$26),$O$26,IF(OR(B29=$N$27),$O$27,IF(OR(B29=$N$21,B29=$N$22,B29=$N$23,B29=$N$24,B29=$N$25),$O$21,"ERR"))) -> ERR
A30: 46164 | B30: =TEXT(A30,"dddd") -> Friday | C30: =VLOOKUP(A30,[1]חגים!$A$2:$C$794,2,FALSE) -> #N/A | D30: =IF(OR(B30=$N$26),$N$18,IF(OR(B30=$N$27),$N$19,IF(OR(B30=$N$21,B30=$N$22,B30=$N$23,B30=$N$24,B30=$N$25),$N$17,"ERR"))) -> ERR | E30: =IF(OR(B30=$N$26),$O$18,IF(OR(B30=$N$27),$O$19,IF(OR(B30=$N$21,B30=$N$22,B30=$N$23,B30=$N$24,B30=$N$25),$O$17,"ERR"))) -> ERR | F30: =IF(OR(B30=$N$26,B30=$N$27),"CLOSED",IF(OR(B30=$N$21,B30=$N$22,B30=$N$23,B30=$N$24,B30=$N$25),$P$17,"ERR")) -> ERR | G30: =IF(OR(B30=$N$26),$O$26,IF(OR(B30=$N$27),$O$27,IF(OR(B30=$N$21,B30=$N$22,B30=$N$23,B30=$N$24,B30=$N$25),$O$21,"ERR"))) -> ERR | Q30: שבת
A31: 46165 | B31: =TEXT(A31,"dddd") -> Saturday | C31: =VLOOKUP(A31,[1]חגים!$A$2:$C$794,2,FALSE) -> #N/A | D31: =IF(OR(B31=$N$26),$N$18,IF(OR(B31=$N$27),$N$19,IF(OR(B31=$N$21,B31=$N$22,B31=$N$23,B31=$N$24,B31=$N$25),$N$17,"ERR"))) -> ERR | E31: =IF(OR(B31=$N$26),$O$18,IF(OR(B31=$N$27),$O$19,IF(OR(B31=$N$21,B31=$N$22,B31=$N$23,B31=$N$24,B31=$N$25),$O$17,"ERR"))) -> ERR | F31: =IF(OR(B31=$N$26,B31=$N$27),"CLOSED",IF(OR(B31=$N$21,B31=$N$22,B31=$N$23,B31=$N$24,B31=$N$25),$P$17,"ERR")) -> ERR | G31: =IF(OR(B31=$N$26),$O$26,IF(OR(B31=$N$27),$O$27,IF(OR(B31=$N$21,B31=$N$22,B31=$N$23,B31=$N$24,B31=$N$25),$O$21,"ERR"))) -> ERR | R31: 16:00-20:00 | S31: 4 | T31: 1
A32: 46166 | B32: =TEXT(A32,"dddd") -> Sunday | C32: =VLOOKUP(A32,[1]חגים!$A$2:$C$794,2,FALSE) -> #N/A | D32: =IF(OR(B32=$N$26),$N$18,IF(OR(B32=$N$27),$N$19,IF(OR(B32=$N$21,B32=$N$22,B32=$N$23,B32=$N$24,B32=$N$25),$N$17,"ERR"))) -> ERR | E32: =IF(OR(B32=$N$26),$O$18,IF(OR(B32=$N$27),$O$19,IF(OR(B32=$N$21,B32=$N$22,B32=$N$23,B32=$N$24,B32=$N$25),$O$17,"ERR"))) -> ERR | F32: =IF(OR(B32=$N$26,B32=$N$27),"CLOSED",IF(OR(B32=$N$21,B32=$N$22,B32=$N$23,B32=$N$24,B32=$N$25),$P$17,"ERR")) -> ERR | G32: =IF(OR(B32=$N$26),$O$26,IF(OR(B32=$N$27),$O$27,IF(OR(B32=$N$21,B32=$N$22,B32=$N$23,B32=$N$24,B32=$N$25),$O$21,"ERR"))) -> ERR
A33: 46167 | B33: =TEXT(A33,"dddd") -> Monday | C33: =VLOOKUP(A33,[1]חגים!$A$2:$C$794,2,FALSE) -> #N/A | D33: =IF(OR(B33=$N$26),$N$18,IF(OR(B33=$N$27),$N$19,IF(OR(B33=$N$21,B33=$N$22,B33=$N$23,B33=$N$24,B33=$N$25),$N$17,"ERR"))) -> ERR | E33: =IF(OR(B33=$N$26),$O$18,IF(OR(B33=$N$27),$O$19,IF(OR(B33=$N$21,B33=$N$22,B33=$N$23,B33=$N$24,B33=$N$25),$O$17,"ERR"))) -> ERR | F33: =IF(OR(B33=$N$26,B33=$N$27),"CLOSED",IF(OR(B33=$N$21,B33=$N$22,B33=$N$23,B33=$N$24,B33=$N$25),$P$17,"ERR")) -> ERR | G33: =IF(OR(B33=$N$26),$O$26,IF(OR(B33=$N$27),$O$27,IF(OR(B33=$N$21,B33=$N$22,B33=$N$23,B33=$N$24,B33=$N$25),$O$21,"ERR"))) -> ERR
A34: 46168 | B34: =TEXT(A34,"dddd") -> Tuesday | C34: =VLOOKUP(A34,[1]חגים!$A$2:$C$794,2,FALSE) -> #N/A | D34: =IF(OR(B34=$N$26),$N$18,IF(OR(B34=$N$27),$N$19,IF(OR(B34=$N$21,B34=$N$22,B34=$N$23,B34=$N$24,B34=$N$25),$N$17,"ERR"))) -> ERR | E34: =IF(OR(B34=$N$26),$O$18,IF(OR(B34=$N$27),$O$19,IF(OR(B34=$N$21,B34=$N$22,B34=$N$23,B34=$N$24,B34=$N$25),$O$17,"ERR"))) -> ERR | F34: =IF(OR(B34=$N$26,B34=$N$27),"CLOSED",IF(OR(B34=$N$21,B34=$N$22,B34=$N$23,B34=$N$24,B34=$N$25),$P$17,"ERR")) -> ERR | G34: =IF(OR(B34=$N$26),$O$26,IF(OR(B34=$N$27),$O$27,IF(OR(B34=$N$21,B34=$N$22,B34=$N$23,B34=$N$24,B34=$N$25),$O$21,"ERR"))) -> ERR
A35: 46169 | B35: =TEXT(A35,"dddd") -> Wednesday | C35: =VLOOKUP(A35,[1]חגים!$A$2:$C$794,2,FALSE) -> #N/A | D35: =IF(OR(B35=$N$26),$N$18,IF(OR(B35=$N$27),$N$19,IF(OR(B35=$N$21,B35=$N$22,B35=$N$23,B35=$N$24,B35=$N$25),$N$17,"ERR"))) -> ERR | E35: =IF(OR(B35=$N$26),$O$18,IF(OR(B35=$N$27),$O$19,IF(OR(B35=$N$21,B35=$N$22,B35=$N$23,B35=$N$24,B35=$N$25),$O$17,"ERR"))) -> ERR | F35: =IF(OR(B35=$N$26,B35=$N$27),"CLOSED",IF(OR(B35=$N$21,B35=$N$22,B35=$N$23,B35=$N$24,B35=$N$25),$P$17,"ERR")) -> ERR | G35: =IF(OR(B35=$N$26),$O$26,IF(OR(B35=$N$27),$O$27,IF(OR(B35=$N$21,B35=$N$22,B35=$N$23,B35=$N$24,B35=$N$25),$O$21,"ERR"))) -> ERR
A36: 46170 | B36: =TEXT(A36,"dddd") -> Thursday | C36: =VLOOKUP(A36,[1]חגים!$A$2:$C$794,2,FALSE) -> #N/A | D36: =IF(OR(B36=$N$26),$N$18,IF(OR(B36=$N$27),$N$19,IF(OR(B36=$N$21,B36=$N$22,B36=$N$23,B36=$N$24,B36=$N$25),$N$17,"ERR"))) -> ERR | E36: =IF(OR(B36=$N$26),$O$18,IF(OR(B36=$N$27),$O$19,IF(OR(B36=$N$21,B36=$N$22,B36=$N$23,B36=$N$24,B36=$N$25),$O$17,"ERR"))) -> ERR | F36: =IF(OR(B36=$N$26,B36=$N$27),"CLOSED",IF(OR(B36=$N$21,B36=$N$22,B36=$N$23,B36=$N$24,B36=$N$25),$P$17,"ERR")) -> ERR | G36: =IF(OR(B36=$N$26),$O$26,IF(OR(B36=$N$27),$O$27,IF(OR(B36=$N$21,B36=$N$22,B36=$N$23,B36=$N$24,B36=$N$25),$O$21,"ERR"))) -> ERR | M36: 0.70833333 | N36: 0.875
A37: 46171 | B37: =TEXT(A37,"dddd") -> Friday | C37: =VLOOKUP(A37,[1]חגים!$A$2:$C$794,2,FALSE) -> #N/A | D37: =IF(OR(B37=$N$26),$N$18,IF(OR(B37=$N$27),$N$19,IF(OR(B37=$N$21,B37=$N$22,B37=$N$23,B37=$N$24,B37=$N$25),$N$17,"ERR"))) -> ERR | E37: =IF(OR(B37=$N$26),$O$18,IF(OR(B37=$N$27),$O$19,IF(OR(B37=$N$21,B37=$N$22,B37=$N$23,B37=$N$24,B37=$N$25),$O$17,"ERR"))) -> ERR | F37: =IF(OR(B37=$N$26,B37=$N$27),"CLOSED",IF(OR(B37=$N$21,B37=$N$22,B37=$N$23,B37=$N$24,B37=$N$25),$P$17,"ERR")) -> ERR | G37: =IF(OR(B37=$N$26),$O$26,IF(OR(B37=$N$27),$O$27,IF(OR(B37=$N$21,B37=$N$22,B37=$N$23,B37=$N$24,B37=$N$25),$O$21,"ERR"))) -> ERR
A38: 46172 | B38: =TEXT(A38,"dddd") -> Saturday | C38: =VLOOKUP(A38,[1]חגים!$A$2:$C$794,2,FALSE) -> #N/A | D38: =IF(OR(B38=$N$26),$N$18,IF(OR(B38=$N$27),$N$19,IF(OR(B38=$N$21,B38=$N$22,B38=$N$23,B38=$N$24,B38=$N$25),$N$17,"ERR"))) -> ERR | E38: =IF(OR(B38=$N$26),$O$18,IF(OR(B38=$N$27),$O$19,IF(OR(B38=$N$21,B38=$N$22,B38=$N$23,B38=$N$24,B38=$N$25),$O$17,"ERR"))) -> ERR | F38: =IF(OR(B38=$N$26,B38=$N$27),"CLOSED",IF(OR(B38=$N$21,B38=$N$22,B38=$N$23,B38=$N$24,B38=$N$25),$P$17,"ERR")) -> ERR | G38: =IF(OR(B38=$N$26),$O$26,IF(OR(B38=$N$27),$O$27,IF(OR(B38=$N$21,B38=$N$22,B38=$N$23,B38=$N$24,B38=$N$25),$O$21,"ERR"))) -> ERR
A39: 46173 | B39: =TEXT(A39,"dddd") -> Sunday | C39: =VLOOKUP(A39,[1]חגים!$A$2:$C$794,2,FALSE) -> #N/A | D39: =IF(OR(B39=$N$26),$N$18,IF(OR(B39=$N$27),$N$19,IF(OR(B39=$N$21,B39=$N$22,B39=$N$23,B39=$N$24,B39=$N$25),$N$17,"ERR"))) -> ERR | E39: =IF(OR(B39=$N$26),$O$18,IF(OR(B39=$N$27),$O$19,IF(OR(B39=$N$21,B39=$N$22,B39=$N$23,B39=$N$24,B39=$N$25),$O$17,"ERR"))) -> ERR | F39: =IF(OR(B39=$N$26,B39=$N$27),"CLOSED",IF(OR(B39=$N$21,B39=$N$22,B39=$N$23,B39=$N$24,B39=$N$25),$P$17,"ERR")) -> ERR | G39: =IF(OR(B39=$N$26),$O$26,IF(OR(B39=$N$27),$O$27,IF(OR(B39=$N$21,B39=$N$22,B39=$N$23,B39=$N$24,B39=$N$25),$O$21,"ERR"))) -> ERR
G40: =SUM(G9:G39) -> 0 | N40: 0.875
E41: אריאל ספא בע"מ | N41: 0.83333333
N42: 0.91666667
...

Sheet דוח מרכז לאישור מנהל
A1: A+ סטריט מול
A2: נוכחות יוני 26
A4: שם העובד : | B4: ניקול אדלמן | C4: נועם תבל | D4: לאון ורחובסקי | E4: ערד קוצר | F4: איתן בר אב | G4: ניב בן חיים | H4: גלעד וייס | I4: בר סידיס | J4: אופל מיוני | K4: לאון ורחובסקי | M4: סה"כ | N4: חיוב מדריכים +קבלה
A5: פירוט | B5: נציגת קבלה | C5: נציגת קבלה | D5: נציגת קבלה | E5: מדריך | F5: מדריך | G5: מדריך | H5: מדריך | I5: מדריך | J5: מדריך | K5: מדריך
A6: שעות רגילות | C6: ='סיכום אמוני סטודיו וקבוצה'!P23 -> 58.75 | D6: ='סיכום אמוני סטודיו וקבוצה'!P22 -> 60 | E6: ='סיכום אמוני סטודיו וקבוצה'!O25 -> 60.5 | F6: ='סיכום אמוני סטודיו וקבוצה'!O20 -> 47.5 | G6: ='סיכום אמוני סטודיו וקבוצה'!O24 -> 56.95 | H6: ='סיכום אמוני סטודיו וקבוצה'!O26 -> 17 | I6: ='סיכום אמוני סטודיו וקבוצה'!O27 -> 11.5 | J6: ='סיכום אמוני סטודיו וקבוצה'!O28 -> 57 | K6: ='סיכום אמוני סטודיו וקבוצה'!O22 -> 45.9 | M6: =SUM(B6:L6) -> 415.1 | N6: =SUM(B25:L26) -> 32143.562
A7: תעריף לפי 125% | C7: 1 | E7: 9 | K7: 0.57 | M7: =SUM(B7:L7) -> 10.57
A8: תעריף לפי 150% | E8: 1 | G8: 3.05 | J8: 5 | M8: =SUM(B8:L8) -> 9.05
A9: תעריף לפי 175% | M9: =SUM(B9:L9) -> 0
A10: תעריף לפי 200% | M10: =SUM(B10:L10) -> 0
A11: תשלום נסיעות בפועל | C11: 100 | D11: 200 | E11: 208.5 | F11: 100 | G11: 100 | H11: 160 | I11: 100 | J11: 100 | M11: =SUM(B11:L11) -> 1068.5
M12: =SUM(B12:L12) -> 0
A13: שונות (בונוס) | M13: =SUM(B13:L13) -> 0
A14: סה"כ חיוב בגין שעות | M14: =SUM(B14:L14) -> 0
A15: סה"כ שעות אמונים אישיים במשמרת | E15: =VLOOKUP(E4,'סיכום אמוני סטודיו וקבוצה'!$F$20:$H$28,3,FALSE) -> 0 | F15: =VLOOKUP(F4,'סיכום אמוני סטודיו וקבוצה'!$F$20:$H$28,3,FALSE) -> 0 | G15: =VLOOKUP(G4,'סיכום אמוני סטודיו וקבוצה'!$F$20:$H$28,3,FALSE) -> 0 | H15: =VLOOKUP(H4,'סיכום אמוני סטודיו וקבוצה'!$F$20:$H$28,3,FALSE) -> 0 | I15: =VLOOKUP(I4,'סיכום אמוני סטודיו וקבוצה'!$F$20:$H$28,3,FALSE) -> 0 | J15: =VLOOKUP(J4,'סיכום אמוני סטודיו וקבוצה'!$F$20:$H$28,3,FALSE) -> 0 | K15: =VLOOKUP(K4,'סיכום אמוני סטודיו וקבוצה'!$F$20:$H$28,3,FALSE) -> 0 | M15: =SUMIF(B15:L15,">0") -> 0
A16: סה"כ שעות אמונים אישיים לא במשמרת | E16: =VLOOKUP(E4,'סיכום אמוני סטודיו וקבוצה'!$F$20:$G$28,2,FALSE) -> 45 | F16: =VLOOKUP(F4,'סיכום אמוני סטודיו וקבוצה'!$F$20:$G$28,2,FALSE) -> 10 | G16: =VLOOKUP(G4,'סיכום אמוני סטודיו וקבוצה'!$F$20:$G$28,2,FALSE) -> 3 | H16: =VLOOKUP(H4,'סיכום אמוני סטודיו וקבוצה'!$F$20:$G$28,2,FALSE) -> 6 | I16: =VLOOKUP(I4,'סיכום אמוני סטודיו וקבוצה'!$F$20:$G$28,2,FALSE) -> 9 | J16: =VLOOKUP(J4,'סיכום אמוני סטודיו וקבוצה'!$F$20:$G$28,2,FALSE) -> 7 | K16: =VLOOKUP(K4,'סיכום אמוני סטודיו וקבוצה'!$F$20:$G$28,2,FALSE) -> 11 | M16: =SUMIF(B16:L16,">0") -> 91
A17: סה"כ שעות אמונים אישיים קבוצתיים | E17: =VLOOKUP(E4,'סיכום אמוני סטודיו וקבוצה'!$F$20:$I$28,4,FALSE) -> 0 | F17: =VLOOKUP(F4,'סיכום אמוני סטודיו וקבוצה'!$F$20:$I$28,4,FALSE) -> 0 | G17: =VLOOKUP(G4,'סיכום אמוני סטודיו וקבוצה'!$F$20:$I$28,4,FALSE) -> 0 | H17: =VLOOKUP(H4,'סיכום אמוני סטודיו וקבוצה'!$F$20:$I$28,4,FALSE) -> 0 | I17: =VLOOKUP(I4,'סיכום אמוני סטודיו וקבוצה'!$F$20:$I$28,4,FALSE) -> 0 | J17: =VLOOKUP(J4,'סיכום אמוני סטודיו וקבוצה'!$F$20:$I$28,4,FALSE) -> 0 | K17: =VLOOKUP(K4,'סיכום אמוני סטודיו וקבוצה'!$F$20:$I$28,4,FALSE) -> 0 | M17: =SUMIF(B17:L17,">0") -> 0
A18: סה"כ שעות אמונים אישיים קבוצתייםלא במשמרת | E18: =VLOOKUP(E4,'סיכום אמוני סטודיו וקבוצה'!$F$20:$J$28,5,FALSE) -> 0 | F18: =VLOOKUP(F4,'סיכום אמוני סטודיו וקבוצה'!$F$20:$J$28,5,FALSE) -> 0 | G18: =VLOOKUP(G4,'סיכום אמוני סטודיו וקבוצה'!$F$20:$J$28,5,FALSE) -> 0 | H18: =VLOOKUP(H4,'סיכום אמוני סטודיו וקבוצה'!$F$20:$J$28,5,FALSE) -> 0 | I18: =VLOOKUP(I4,'סיכום אמוני סטודיו וקבוצה'!$F$20:$J$28,5,FALSE) -> 0 | J18: =VLOOKUP(J4,'סיכום אמוני סטודיו וקבוצה'!$F$20:$J$28,5,FALSE) -> 0 | K18: =VLOOKUP(K4,'סיכום אמוני סטודיו וקבוצה'!$F$20:$J$28,5,FALSE) -> 0 | M18: =SUMIF(B18:L18,">0") -> 0
A19: סה"כ שעות אימוני סטודיו | E19: =VLOOKUP(E4,'סיכום אמוני סטודיו וקבוצה'!$A$20:$D$28,2,FALSE) -> 0 | F19: =VLOOKUP(F4,'סיכום אמוני סטודיו וקבוצה'!$A$20:$D$28,2,FALSE) -> 0 | G19: =VLOOKUP(G4,'סיכום אמוני סטודיו וקבוצה'!$A$20:$D$28,2,FALSE) -> 0 | H19: =VLOOKUP(H4,'סיכום אמוני סטודיו וקבוצה'!$A$20:$D$28,2,FALSE) -> 0 | I19: =VLOOKUP(I4,'סיכום אמוני סטודיו וקבוצה'!$A$20:$D$28,2,FALSE) -> 0 | J19: =VLOOKUP(J4,'סיכום אמוני סטודיו וקבוצה'!$A$20:$D$28,2,FALSE) -> 0 | K19: =VLOOKUP(K4,'סיכום אמוני סטודיו וקבוצה'!$A$20:$D$28,2,FALSE) -> 0 | M19: =SUMIF(B19:L19,">0") -> 0
A20: סה"כ אימוני סטודיו אישי במשמרת | E20: =VLOOKUP(E4,'סיכום אמוני סטודיו וקבוצה'!$F$20:$L$28,6,FALSE) -> 0 | F20: =VLOOKUP(F4,'סיכום אמוני סטודיו וקבוצה'!$F$20:$L$28,6,FALSE) -> 0 | G20: =VLOOKUP(G4,'סיכום אמוני סטודיו וקבוצה'!$F$20:$L$28,6,FALSE) -> 0 | H20: =VLOOKUP(H4,'סיכום אמוני סטודיו וקבוצה'!$F$20:$L$28,6,FALSE) -> 0 | I20: =VLOOKUP(I4,'סיכום אמוני סטודיו וקבוצה'!$F$20:$L$28,6,FALSE) -> 0 | J20: =VLOOKUP(J4,'סיכום אמוני סטודיו וקבוצה'!$F$20:$L$28,6,FALSE) -> 0 | K20: =VLOOKUP(K4,'סיכום אמוני סטודיו וקבוצה'!$F$20:$L$28,6,FALSE) -> 0 | M20: =SUMIF(B20:L20,">0") -> 0
A21: סה"כ אימוני סטודיו אישי לא במשמרת | E21: =VLOOKUP(E4,'סיכום אמוני סטודיו וקבוצה'!$F$20:$L$28,7,FALSE) -> 0 | F21: =VLOOKUP(F4,'סיכום אמוני סטודיו וקבוצה'!$F$20:$L$28,7,FALSE) -> 0 | G21: =VLOOKUP(G4,'סיכום אמוני סטודיו וקבוצה'!$F$20:$L$28,7,FALSE) -> 0 | H21: =VLOOKUP(H4,'סיכום אמוני סטודיו וקבוצה'!$F$20:$L$28,7,FALSE) -> 0 | I21: =VLOOKUP(I4,'סיכום אמוני סטודיו וקבוצה'!$F$20:$L$28,7,FALSE) -> 0 | J21: =VLOOKUP(J4,'סיכום אמוני סטודיו וקבוצה'!$F$20:$L$28,7,FALSE) -> 0 | K21: =VLOOKUP(K4,'סיכום אמוני סטודיו וקבוצה'!$F$20:$L$28,7,FALSE) -> 0 | M21: =SUMIF(B21:L21,">0") -> 0
A22: סה"כ שעות אימוני קבוצות במשמרת | E22: =VLOOKUP(E4,'סיכום אמוני סטודיו וקבוצה'!$A$20:$D$28,4,FALSE) -> 0 | F22: =VLOOKUP(F4,'סיכום אמוני סטודיו וקבוצה'!$A$20:$D$28,4,FALSE) -> 0 | G22: =VLOOKUP(G4,'סיכום אמוני סטודיו וקבוצה'!$A$20:$D$28,4,FALSE) -> 0 | H22: =VLOOKUP(H4,'סיכום אמוני סטודיו וקבוצה'!$A$20:$D$28,4,FALSE) -> 0 | I22: =VLOOKUP(I4,'סיכום אמוני סטודיו וקבוצה'!$A$20:$D$28,4,FALSE) -> 0 | J22: =VLOOKUP(J4,'סיכום אמוני סטודיו וקבוצה'!$A$20:$D$28,4,FALSE) -> 0 | K22: =VLOOKUP(K4,'סיכום אמוני סטודיו וקבוצה'!$A$20:$D$28,4,FALSE) -> 0 | M22: =SUMIF(B22:L22,">0") -> 0
A23: סה"כ שעות אימוני קבוצות לא במשמרת | E23: =VLOOKUP(E4,'סיכום אמוני סטודיו וקבוצה'!$A$20:$D$28,3,FALSE) -> 17 | F23: =VLOOKUP(F4,'סיכום אמוני סטודיו וקבוצה'!$A$20:$D$28,3,FALSE) -> 0 | G23: =VLOOKUP(G4,'סיכום אמוני סטודיו וקבוצה'!$A$20:$D$28,3,FALSE) -> 0 | H23: =VLOOKUP(H4,'סיכום אמוני סטודיו וקבוצה'!$A$20:$D$28,3,FALSE) -> 0 | I23: =VLOOKUP(I4,'סיכום אמוני סטודיו וקבוצה'!$A$20:$D$28,3,FALSE) -> 1 | J23: =VLOOKUP(J4,'סיכום אמוני סטודיו וקבוצה'!$A$20:$D$28,3,FALSE) -> 6 | K23: =VLOOKUP(K4,'סיכום אמוני סטודיו וקבוצה'!$A$20:$D$28,3,FALSE) -> 0 | M23: =SUMIF(B23:L23,">0") -> 24
A24: סה"כ שעות אירוע חברה | E24: =VLOOKUP(E4,'סיכום אמוני סטודיו וקבוצה'!$F$20:$P$28,8,FALSE) -> 0 | F24: =VLOOKUP(F4,'סיכום אמוני סטודיו וקבוצה'!$F$20:$P$28,8,FALSE) -> 0 | G24: =VLOOKUP(G4,'סיכום אמוני סטודיו וקבוצה'!$F$20:$P$28,8,FALSE) -> 0 | H24: =VLOOKUP(H4,'סיכום אמוני סטודיו וקבוצה'!$F$20:$P$28,8,FALSE) -> 0 | I24: =VLOOKUP(I4,'סיכום אמוני סטודיו וקבוצה'!$F$20:$P$28,8,FALSE) -> 0 | J24: =VLOOKUP(J4,'סיכום אמוני סטודיו וקבוצה'!$F$20:$P$28,8,FALSE) -> 0 | K24: =VLOOKUP(K4,'סיכום אמוני סטודיו וקבוצה'!$F$20:$P$28,8,FALSE) -> 0 | M24: =SUMIF(B24:L24,">0") -> 0
A25: חיוב מאמנים שעות רגילות | E25: =IF(E5="נציגת קבלה",E7*$L$38,E7*$E$38)+IF(E5="נציגת קבלה",E6*$L$37,E6*$E$37)+IF(E5="נציגת קבלה",E8*$L$39,E8*$E$39)+IF(E5="נציגת קבלה",E9*$L$40,E9*$E$40)+IF(E5="נציגת קבלה",E10*$L$41,E10*$E$41)+E13+E11 -> 4952.25 | F25: =IF(F5="נציגת קבלה",F7*$L$38,F7*$E$38)+IF(F5="נציגת קבלה",F6*$L$37,F6*$E$37)+IF(F5="נציגת קבלה",F8*$L$39,F8*$E$39)+IF(F5="נציגת קבלה",F9*$L$40,F9*$E$40)+IF(F5="נציגת קבלה",F10*$L$41,F10*$E$41)+F13+F11 -> 3662.5 | G25: =IF(G5="נציגת קבלה",G7*$L$38,G7*$E$38)+IF(G5="נציגת קבלה",G6*$L$37,G6*$E$37)+IF(G5="נציגת קבלה",G8*$L$39,G8*$E$39)+IF(G5="נציגת קבלה",G9*$L$40,G9*$E$40)+IF(G5="נציגת קבלה",G10*$L$41,G10*$E$41)+G13+G11 -> 4485.625 | H25: =IF(H5="נציגת קבלה",H7*$L$38,H7*$E$38)+IF(H5="נציגת קבלה",H6*$L$37,H6*$E$37)+IF(H5="נציגת קבלה",H8*$L$39,H8*$E$39)+IF(H5="נציגת קבלה",H9*$L$40,H9*$E$40)+IF(H5="נציגת קבלה",H10*$L$41,H10*$E$41)+H13+H11 -> 1435 | I25: =IF(I5="נציגת קבלה",I7*$L$38,I7*$E$38)+IF(I5="נציגת קבלה",I6*$L$37,I6*$E$37)+IF(I5="נציגת קבלה",I8*$L$39,I8*$E$39)+IF(I5="נציגת קבלה",I9*$L$40,I9*$E$40)+IF(I5="נציגת קבלה",I10*$L$41,I10*$E$41)+I13+I11 -> 962.5 | J25: =IF(J5="נציגת קבלה",J7*$L$38,J7*$E$38)+IF(J5="נציגת קבלה",J6*$L$37,J6*$E$37)+IF(J5="נציגת קבלה",J8*$L$39,J8*$E$39)+IF(J5="נציגת קבלה",J9*$L$40,J9*$E$40)+IF(J5="נציגת קבלה",J10*$L$41,J10*$E$41)+J13+J11 -> 4562.5 | K25: =IF(K5="נציגת קבלה",K7*$L$38,K7*$E$38)+IF(K5="נציגת קבלה",K6*$L$37,K6*$E$37)+IF(K5="נציגת קבלה",K8*$L$39,K8*$E$39)+IF(K5="נציגת קבלה",K9*$L$40,K9*$E$40)+IF(K5="נציגת קבלה",K10*$L$41,K10*$E$41)+K13+K11 -> 3453.1875 | N25: =SUM(B25:L25) -> 23513.562
A26: חיוב קבלה שעות רגילות | B26: =IF(B5="נציגת קבלה",B7*$L$38,B7*$E$38)+IF(B5="נציגת קבלה",B6*$L$37,B6*$E$37)+IF(B5="נציגת קבלה",B8*$L$39,B8*$E$39)+IF(B5="נציגת קבלה",B9*$L$40,B9*$E$40)+IF(B5="נציגת קבלה",B10*$L$41,B10*$E$41)+B13+B11 -> 0 | C26: =IF(C5="נציגת קבלה",C7*$L$38,C7*$E$38)+IF(C5="נציגת קבלה",C6*$L$37,C6*$E$37)+IF(C5="נציגת קבלה",C8*$L$39,C8*$E$39)+IF(C5="נציגת קבלה",C9*$L$40,C9*$E$40)+IF(C5="נציגת קבלה",C10*$L$41,C10*$E$41)+C13+C11 -> 4230 | D26: =IF(D5="נציגת קבלה",D7*$L$38,D7*$E$38)+IF(D5="נציגת קבלה",D6*$L$37,D6*$E$37)+IF(D5="נציגת קבלה",D8*$L$39,D8*$E$39)+IF(D5="נציגת קבלה",D9*$L$40,D9*$E$40)+IF(D5="נציגת קבלה",D10*$L$41,D10*$E$41)+D13+D11 -> 4400 | N26: =SUM(B26:L26) -> 8630
A27: חיוב אימונים אישיים | E27: =E15*$O$38+E16*$O$38+E17*$N$40+E18*$N$40+E20*$R$37+E21*$R$37 -> 5175 | F27: =F15*$O$38+F16*$O$38+F17*$N$40+F18*$N$40+F20*$R$37+F21*$R$37 -> 1150 | G27: =G15*$O$38+G16*$O$38+G17*$N$40+G18*$N$40+G20*$R$37+G21*$R$37 -> 345 | H27: =H15*$O$38+H16*$O$38+H17*$N$40+H18*$N$40+H20*$R$37+H21*$R$37 -> 690 | I27: =I15*$O$38+I16*$O$38+I17*$N$40+I18*$N$40+I20*$R$37+I21*$R$37 -> 1035 | J27: =J15*$O$38+J16*$O$38+J17*$N$40+J18*$N$40+J20*$R$37+J21*$R$37 -> 805 | K27: =K15*$O$38+K16*$O$38+K17*$N$40+K18*$N$40+K20*$R$37+K21*$R$37 -> 1265 | N27: =SUM(B27:L27) -> 10465
A28: חיוב אימונים סטודיו | E28: =E19*$P$37 -> 0 | F28: =F19*$P$37 -> 0 | G28: =G19*$P$37 -> 0 | H28: =H19*$P$37 -> 0 | I28: =I19*$P$37 -> 0 | J28: =J19*$P$37 -> 0 | K28: =K19*$P$37 -> 0 | N28: =SUM(B28:L28) -> 0
A29: חיוב אימוני קבוצות | E29: =E22*$N$37+E23*$N$38 -> 2210 | F29: =F22*$N$37+F23*$N$38 -> 0 | G29: =G22*$N$37+G23*$N$38 -> 0 | H29: =H22*$N$37+H23*$N$38 -> 0 | I29: =I22*$N$37+I23*$N$38 -> 130 | J29: =J22*$N$37+J23*$N$38 -> 780 | K29: =K22*$N$37+K23*$N$38 -> 0 | N29: =SUM(B29:L29) -> 3120
A30: חיוב אירוע חברה | E30: =E24*$S$37 -> 0 | F30: =F24*$S$37 -> 0 | G30: =G24*$S$37 -> 0 | H30: =H24*$S$37 -> 0 | I30: =I24*$S$37 -> 0 | J30: =J24*$S$37 -> 0 | K30: =K24*$S$37 -> 0 | N30: =SUM(B30:L30) -> 0
C31: =מכירות!N7 -> 1992.6 | D31: =מכירות!N4 -> 1614.6 | E31: =מכירות!N8 -> 54 | H31: =מכירות!N6 -> 194.4 | I31: =מכירות!N5 -> 64.8 | J31: =מכירות!N9 -> 81
A32: תשלום נסיעות בפועל | E32: =-SUM(E15+E17)*$E$37 -> 0 | F32: =-SUM(F15+F17)*$E$37 -> 0 | G32: =-SUM(G15+G17)*$E$37 -> 0 | H32: =-SUM(H15+H17)*$E$37 -> 0 | I32: =-SUM(I15+I17)*$E$37 -> 0 | J32: =-SUM(J15+J17)*$E$37 -> 0 | K32: =-SUM(K15+K17)*$E$37 -> 0 | N32: =SUM(E32:L32) -> 0
A33: =M11 -> 1068.5
B34: =SUM(B25:B33) -> 0 | C34: =SUM(C25:C33) -> 6222.6 | D34: =SUM(D25:D33) -> 6014.6 | E34: =SUM(E25:E33) -> 12391.25 | F34: =SUM(F25:F33) -> 4812.5 | G34: =SUM(G25:G33) -> 4830.625 | H34: =SUM(H25:H33) -> 2319.4 | I34: =SUM(I25:I33) -> 2192.3 | ... K34: =SUM(K25:K33) -> 4718.1875
L35: =K34+D34 -> 10732.788
A36: מדריכים | B36: ברוטו עובד | C36: סוציאליות 30% | D36: סה"כ עלות מעביד | E36: עלות חיוב לפרוייקט | G36: נציגות קבלה | H36: ברוטו עובד | J36: סוציאליות 25% | K36: סה"כ עלות מעביד | L36: עלות חיוב לפרוייקט | N36: אימוני קבוצות | O36: אימונים אישי | P36: אימון סטודיו קטן | Q36: סטודיו פיאלטיס | R36: אישי קבוצתי | S36: אימוני חברה
A37: 1 | B37: 40 | C37: =B37*1.3 -> 52 | D37: =C37 -> 52 | E37: 75 | G37: 1 | H37: 40 | J37: =H37*1.3 -> 52 | K37: =+J37 -> 52 | L37: 70 | N37: 55 | O37: 40 | P37: 180 | Q37: 185 | R37: 150 | S37: 250
A38: 1.25 | B38: =$B$37*A38 -> 50 | C38: =B38*1.33 -> 66.5 | D38: =+C38 -> 66.5 | E38: =$E$37*0.25 -> 18.75 | G38: 1.25 | H38: =H37*G38 -> 50 | J38: =H38*1.33 -> 66.5 | K38: =+J38 -> 66.5 | L38: =$L$37*0.25 -> 17.5 | N38: 130 | O38: 115
A39: 1.5 | B39: =$B$37*A39 -> 60 | C39: =B39*1.33 -> 79.8 | D39: =+C39 -> 79.8 | E39: =$E$37*0.5 -> 37.5 | G39: 1.5 | H39: =H37*G39 -> 60 | J39: =H39*1.33 -> 79.8 | K39: =+J39 -> 79.8 | L39: =$L$37*0.5 -> 35 | N39: לא במשמרת
A40: 1.75 | B40: =$B$37*A40 -> 70 | C40: =B40*1.33 -> 93.1 | D40: =+C40 -> 93.1 | E40: =$E$37*0.75 -> 56.25 | G40: 1.75 | H40: =H37*G40 -> 70 | J40: =H40*1.33 -> 93.1 | K40: =+J40 -> 93.1 | L40: =$L$37*0.75 -> 52.5 | N40: 150
A41: 2 | B41: =$B$37*A41 -> 80 | C41: =B41*1.33 -> 106.4 | D41: =+C41 -> 106.4 | E41: =$E$37*1 -> 75 | G41: 2 | H41: =H37*G41 -> 80 | J41: =H41*1.33 -> 106.4 | K41: =+J41 -> 106.4 | L41: =$L$37*1 -> 70
...

Sheet סיכום אמוני סטודיו וקבוצה
A1: אימונים קבוצתיים וסטודיו | H1: אימונים אישיים | N1: חדר כושר | Z1: עלות לאישי כולל מע״מ | AA1: עלות לאימון קבוצה/סטודיו | AB1: עלות לשעת משמרת
A2: תוויות שורה | B2: כמות אימונים סטודיו | C2: לא במשמרת אימונים קבוצתיים | D2: במשמרת קבוצתיים מועדון | F2: תוויות שורה | G2: אימונים אישיים לא במשמרת | H2: כמות אימונים אישיים במשמרת | I2: אימונים אישיים קבוצתיים במשמרת | J2: אימונים אישיים קבוצתיים לא במשמרת | K2: אימונים אישיים סטודיו במשמרת | L2: אימונים אישיים סטודיו לא במשמרת | N2: משמרת חדר כושר, חיצוני | O2: משמרת חדר כושר, שכירים | P2: ש"ע פקידת קבלה/מכירות שכירים | Y2: מורן קליין | AA2: 150
A3: מורן קליין | B3: 4 | F3: מורן קליין | Y3: עידן וקסר | Z3: 129.8 | AA3: 177
A4: יובל לוי | B4: 0 | F4: יובל לוי
A5: עידן וקסר | B5: 14 | F5: עידן וקסר | G5: 36
A6: מאיה זיידנר | B6: 1 | F6: מאיה זיידנר | Y6: רחלי בויום | AA6: 120
A7: רוני בר | B7: 2 | F7: רוני בר | Y7: ניר אייזנבך | Z7: 129.8 | AA7: 200.6
A8: גיל טל | B8: 2 | F8: גיל טל | Y8: עופרי אורן | AA8: 200
A9: רן קיסלב | F9: רן קיסלב | G9: 1 | N9: 1
A10: ניר אייזנבך | B10: 35 | F10: ניר אייזנבך | G10: 27 | Y10: יעלה תורן | AA10: 140
A11: אביבית אלימלך | B11: 8 | F11: אביבית אלימלך | Y11: בר טלמור | AA11: 150
A12: אורלי באומל | B12: 2 | F12: אורלי באומל | Y12: לינוי מזרחי | AA12: 120
A13: נועה כסיף | B13: 8 | F13: נועה כסיף | Y13: זוהר בנהדירם | AA13: 190
A14: לירון ניסן | B14: 18 | F14: לירון ניסן
A15: נעמה שפירא | B15: 10 | F15: נעמה שפירא | Y15: ליהי קינר | AA15: 130
A16: לנה ברואון | B16: 4 | F16: לנה ברואון | Y16: לירון ניסן | AA16: 170
A17: נוי אסרף | B17: 9 | F17: נוי אסרף | G17: 20 | N17: 10
A18: ספיר הורוביץ | B18: 6 | F18: ספיר הורוביץ | Y18: נוי אסרף | Z18: 110 | AA18: 150 | AB18: 112.5
A19: עידו גליקו | F19: עידו גליקו | G19: 85 | N19: 10 | Y19: נוי פרוינדר | AA19: 140
A20: איתן בר אב | F20: איתן בר אב | G20: 10 | O20: =57.5-G20 -> 47.5 | Y20: ספיר הורוביץ | AA20: 140
A21: ניקול אדלמן | F21: ניקול אדלמן | Y21: נועם שליו | AA21: 120
A22: לאון ורחובסקי | F22: לאון ורחובסקי | G22: 11 | O22: =116.9-G22-P22 -> 45.9 | P22: 60 | Y22: מיכל לוק | AA22: 200
A23: נועם תבל | F23: נועם תבל | P23: 58.75 | Y23: עומר לוי | AA23: 130
A24: ניב בן חיים | F24: ניב בן חיים | G24: 3 | O24: =59.95-G24 -> 56.95 | Y24: נטע חן | AA24: 200
A25: ערד קוצר | C25: 17 | F25: ערד קוצר | G25: 45 | O25: =122.5-G25-C25 -> 60.5 | Y25: עידו גליקו | Z25: 110 | AA25: 150 | AB25: 60.677419
A26: גלעד וייס | F26: גלעד וייס | G26: 6 | O26: =23-G26 -> 17
A27: בר סידיס | C27: 1 | F27: בר סידיס | G27: 9 | O27: =21.5-G27-C27 -> 11.5
A28: אופל מיוני | C28: 6 | F28: אופל מיוני | G28: 7 | O28: =70-G28-C28 -> 57
A30: סכום כולל | B30: =SUM(B3:B28) -> 123 | C30: =SUM(C3:C28) -> 24 | D30: =SUM(D3:D28) -> 0 | G30: =SUM(G3:G28) -> 260 | H30: =SUM(H3:H28) -> 0 | I30: =SUM(I3:I28) -> 0 | J30: =SUM(J3:J28) -> 0 | K30: =SUM(K3:K28) -> 0 | L30: =SUM(L3:L28) -> 0 | N30: =SUM(N3:N28) -> 21 | O30: =SUM(O3:O28) -> 296.35 | P30: =SUM(P3:P28) -> 118.75 | Q30: =SUM(B30:P30) -> 843.1 | T30: =SUM(B30:P30) -> 843.1
A35: סה"כ שיעורי סטודיו מאמנים חיצוניים | B35: סה"כ שיעורי סטודיו מאמנים פנימיים לא במשמרת | C35: סה"כ שיעורי מועדון מאמנים חיצוניים | D35: סה"כ שיעורי מועדון מאמנים חיצוניים, לא במשמרת | E35: סה"כ שיעורי קבוצתיים במשמרת מאמנים פנימיים | F35: סה"כ שיעורי קבוצתיים לא במשמרת מאמנים פנימיים | G35: סה"כ אימונים אישיים לא במשמרת | H35: סה"כ אימונים אישיים לא במשמרת מאמן חיצוני | I35: סה"כ אימונים אישי קבוצתי לא במשמרת מאמן חיצוני | J35: סה"כ אימונים אישיים במשמרת | K35: סה"כ אימונים אישיים קבוצתיים במשמרת | L35: סה"כ אימונים אישיים קבוצתיים לא במשמרת | M35: סה"כ אימונים אישיים סטודיו במשמרת | N35: סה"כ אימונים אישיים סטודיו לא במשמרת | O35: סה"כ משמרת חדר כושר חיצוניים | P35: סה"כ משמרת חדר כושר פנימי משמרת | Q35: סה"כ פקידת קבלה/מכירות | R35: סה"כ משמרת קבלה פנימי משמרת | S35: סה"כ
A36: =DSUM(A42:N68,B42,A71:A90) -> 123 | C36: =DSUM(A42:N70,C42,A73:A90) -> 0 | D36: 0 | E36: =DSUM(A42:N70,C42,B73:B83) -> 0 | F36: =DSUM(A42:N70,D42,B73:B83) -> 24 | G36: 91 | H36: 169 | I36: =DSUM(A42:N70,H42,A73:A90) -> 0 | J36: =DSUM(A42:N70,E42,B73:B83) -> 0 | K36: =DSUM(A42:N70,G42,A73:A90)+DSUM(A42:N70,G42,B73:B83) -> 0 | L36: =DSUM(A42:N70,H42,B73:B83) -> 0 | M36: =DSUM(A42:N70,I42,B73:B83) -> 0 | N36: =DSUM(A42:N70,J42,B73:B83) -> 0 | O36: =DSUM(A42:N70,K42,A73:A90) -> 21 | P36: =DSUM(A42:N70,L42,B73:B93) -> 296.35 | Q36: 119 | R36: 0 | S36: =SUM(A36:R36) -> 843.35
B41: אימונים קבוצתיים | E41: אימונים אישיים | K41: שעות | L41: שעות | M41: שעות
A42: שם המדריך | B42: מתקיים סטודיו | C42: מתקיים מועדון - במשמרת | D42: מתקיים מועדון - לא במשמרת | E42: אישי במשמרת | F42: אישי לא במשמרת | G42: אישי קבוצתי במשמרת | H42: אישי קבוצתי לא במשמרת | I42: אישי סטודיו במשמרת | J42: אישי סטודיו לא במשמרת | K42: שעות חד"כ מאמן חיצוני | L42: שעות חד"כ מאמן שכיר | M42: קבלה/מכירות שכיר | N42: סהכ
A43: מורן קליין | B43: =VLOOKUP(A43,$A$3:$D$29,2,FALSE) -> 4 | C43: =VLOOKUP(A43,$A$3:$D$29,4,FALSE) -> 0 | D43: =VLOOKUP(A43,$A$3:$D$29,3,FALSE) -> 0 | E43: =VLOOKUP(A43,$F$3:$L$29,3,FALSE) -> 0 | F43: =VLOOKUP(A43,$F$3:$L$29,2,FALSE) -> 0 | G43: =VLOOKUP(A43,$F$3:$L$29,4,FALSE) -> 0 | H43: =VLOOKUP(A43,$F$3:$L$29,5,FALSE) -> 0 | I43: =VLOOKUP(A43,$F$3:$L$29,6,FALSE) -> 0 | J43: =VLOOKUP(A43,$F$3:$L$29,7,FALSE) -> 0 | K43: =VLOOKUP(A43,$F$3:$P$29,9,FALSE) -> 0 | L43: =VLOOKUP(A43,$F$3:$P$29,10,FALSE) -> 0 | M43: =VLOOKUP(A43,$F$3:$P$28,11,FALSE) -> 0 | N43: =SUM(B43:M43) -> 4
A44: יובל לוי | B44: =VLOOKUP(A44,$A$3:$D$29,2,FALSE) -> 0 | C44: =VLOOKUP(A44,$A$3:$D$29,4,FALSE) -> 0 | D44: =VLOOKUP(A44,$A$3:$D$29,3,FALSE) -> 0 | E44: =VLOOKUP(A44,$F$3:$L$29,3,FALSE) -> 0 | F44: =VLOOKUP(A44,$F$3:$L$29,2,FALSE) -> 0 | G44: =VLOOKUP(A44,$F$3:$L$29,4,FALSE) -> 0 | H44: =VLOOKUP(A44,$F$3:$L$29,5,FALSE) -> 0 | I44: =VLOOKUP(A44,$F$3:$L$29,6,FALSE) -> 0 | J44: =VLOOKUP(A44,$F$3:$L$29,7,FALSE) -> 0 | K44: =VLOOKUP(A44,$F$3:$P$29,9,FALSE) -> 0 | L44: =VLOOKUP(A44,$F$3:$P$29,10,FALSE) -> 0 | M44: =VLOOKUP(A44,$F$3:$P$28,11,FALSE) -> 0 | N44: =SUM(B44:M44) -> 0
A45: עידן וקסר | B45: =VLOOKUP(A45,$A$3:$D$29,2,FALSE) -> 14 | C45: =VLOOKUP(A45,$A$3:$D$29,4,FALSE) -> 0 | D45: =VLOOKUP(A45,$A$3:$D$29,3,FALSE) -> 0 | E45: =VLOOKUP(A45,$F$3:$L$29,3,FALSE) -> 0 | F45: =VLOOKUP(A45,$F$3:$L$29,2,FALSE) -> 36 | G45: =VLOOKUP(A45,$F$3:$L$29,4,FALSE) -> 0 | H45: =VLOOKUP(A45,$F$3:$L$29,5,FALSE) -> 0 | I45: =VLOOKUP(A45,$F$3:$L$29,6,FALSE) -> 0 | J45: =VLOOKUP(A45,$F$3:$L$29,7,FALSE) -> 0 | K45: =VLOOKUP(A45,$F$3:$P$29,9,FALSE) -> 0 | L45: =VLOOKUP(A45,$F$3:$P$29,10,FALSE) -> 0 | M45: =VLOOKUP(A45,$F$3:$P$28,11,FALSE) -> 0 | N45: =SUM(B45:M45) -> 50
A46: מאיה זיידנר | B46: =VLOOKUP(A46,$A$3:$D$29,2,FALSE) -> 1 | C46: =VLOOKUP(A46,$A$3:$D$29,4,FALSE) -> 0 | D46: =VLOOKUP(A46,$A$3:$D$29,3,FALSE) -> 0 | E46: =VLOOKUP(A46,$F$3:$L$29,3,FALSE) -> 0 | F46: =VLOOKUP(A46,$F$3:$L$29,2,FALSE) -> 0 | G46: =VLOOKUP(A46,$F$3:$L$29,4,FALSE) -> 0 | H46: =VLOOKUP(A46,$F$3:$L$29,5,FALSE) -> 0 | I46: =VLOOKUP(A46,$F$3:$L$29,6,FALSE) -> 0 | J46: =VLOOKUP(A46,$F$3:$L$29,7,FALSE) -> 0 | K46: =VLOOKUP(A46,$F$3:$P$29,9,FALSE) -> 0 | L46: =VLOOKUP(A46,$F$3:$P$29,10,FALSE) -> 0 | M46: =VLOOKUP(A46,$F$3:$P$28,11,FALSE) -> 0 | N46: =SUM(B46:M46) -> 1 | Q46: =Q30-S36 -> -0.25
A47: רוני בר | B47: =VLOOKUP(A47,$A$3:$D$29,2,FALSE) -> 2 | C47: =VLOOKUP(A47,$A$3:$D$29,4,FALSE) -> 0 | D47: =VLOOKUP(A47,$A$3:$D$29,3,FALSE) -> 0 | E47: =VLOOKUP(A47,$F$3:$L$29,3,FALSE) -> 0 | F47: =VLOOKUP(A47,$F$3:$L$29,2,FALSE) -> 0 | G47: =VLOOKUP(A47,$F$3:$L$29,4,FALSE) -> 0 | H47: =VLOOKUP(A47,$F$3:$L$29,5,FALSE) -> 0 | I47: =VLOOKUP(A47,$F$3:$L$29,6,FALSE) -> 0 | J47: =VLOOKUP(A47,$F$3:$L$29,7,FALSE) -> 0 | K47: =VLOOKUP(A47,$F$3:$P$29,9,FALSE) -> 0 | L47: =VLOOKUP(A47,$F$3:$P$29,10,FALSE) -> 0 | M47: =VLOOKUP(A47,$F$3:$P$28,11,FALSE) -> 0 | N47: =SUM(B47:M47) -> 2
A48: גיל טל | B48: =VLOOKUP(A48,$A$3:$D$29,2,FALSE) -> 2 | C48: =VLOOKUP(A48,$A$3:$D$29,4,FALSE) -> 0 | D48: =VLOOKUP(A48,$A$3:$D$29,3,FALSE) -> 0 | E48: =VLOOKUP(A48,$F$3:$L$29,3,FALSE) -> 0 | F48: =VLOOKUP(A48,$F$3:$L$29,2,FALSE) -> 0 | G48: =VLOOKUP(A48,$F$3:$L$29,4,FALSE) -> 0 | H48: =VLOOKUP(A48,$F$3:$L$29,5,FALSE) -> 0 | I48: =VLOOKUP(A48,$F$3:$L$29,6,FALSE) -> 0 | J48: =VLOOKUP(A48,$F$3:$L$29,7,FALSE) -> 0 | K48: =VLOOKUP(A48,$F$3:$P$29,9,FALSE) -> 0 | L48: =VLOOKUP(A48,$F$3:$P$29,10,FALSE) -> 0 | M48: =VLOOKUP(A48,$F$3:$P$28,11,FALSE) -> 0 | N48: =SUM(B48:M48) -> 2
A49: רן קיסלב | B49: =VLOOKUP(A49,$A$3:$D$29,2,FALSE) -> 0 | C49: =VLOOKUP(A49,$A$3:$D$29,4,FALSE) -> 0 | D49: =VLOOKUP(A49,$A$3:$D$29,3,FALSE) -> 0 | E49: =VLOOKUP(A49,$F$3:$L$29,3,FALSE) -> 0 | F49: =VLOOKUP(A49,$F$3:$L$29,2,FALSE) -> 1 | G49: =VLOOKUP(A49,$F$3:$L$29,4,FALSE) -> 0 | H49: =VLOOKUP(A49,$F$3:$L$29,5,FALSE) -> 0 | I49: =VLOOKUP(A49,$F$3:$L$29,6,FALSE) -> 0 | J49: =VLOOKUP(A49,$F$3:$L$29,7,FALSE) -> 0 | K49: =VLOOKUP(A49,$F$3:$P$29,9,FALSE) -> 1 | L49: =VLOOKUP(A49,$F$3:$P$29,10,FALSE) -> 0 | M49: =VLOOKUP(A49,$F$3:$P$28,11,FALSE) -> 0 | N49: =SUM(B49:M49) -> 2
...

Sheet חילנט
D1: מס עובד | E1: שם משפחה | F1: סה"כ לשכר | G1: רגילות 1.00 | H1: שנ 100% | I1: שנ 125% | J1: שנ 150% | K1: אימון אישי (הסכם 680 ) | L1: אימון קבוצתי (הסכם 680 ) | M1: אימון זוגי(הסכם 680 ) | N1: סה"כ שעות פרוייקט
D2: סה"כ ורחובסקי לאוניד | F2: 116.9 | G2: 116.33 | I2: 0.57 | K2: 11
D3: סה"כ קוצר ערד | F3: 122.5 | G3: 112.5 | I3: 9 | J3: 1 | K3: 44 | L3: 17 | M3: 1
D4: סה"כ בראב איתן | F4: 57.5 | G4: 57.5 | K4: 10 | N4: 15
D5: סה"כ וייס גלעד | F5: 23 | G5: 23 | K5: 6
D6: סה"כ סידס בר | F6: 21.5 | G6: 21.5 | K6: 9 | L6: 1
D7: סה"כ מיוני אופל | F7: 70 | G7: 63 | H7: 2 | J7: 5 | K7: 7 | L7: 6 | N7: 1
D8: סה"כ תבל נועם | F8: 59.75 | G8: 58.75 | I8: 1
D9: סה"כ בן חיים ניב | F9: 59.95 | G9: 55.9 | H9: 1 | J9: 3.05 | M9: 3
D10: סה"כ כללי | F10: =SUM(F2:F9) -> 531.1 | G10: =SUM(G2:G9) -> 508.48 | H10: =SUM(H2:H9) -> 3 | I10: =SUM(I2:I9) -> 10.57 | J10: =SUM(J2:J9) -> 9.05 | K10: =SUM(K2:K9) -> 87 | L10: =SUM(L2:L9) -> 24 | M10: =SUM(M2:M9) -> 4 | N10: =SUM(N2:N9) -> 16

Sheet חיוב יזם
D3: חיוב יזם - חדר כושר | F3: ='ריכוז שעות'!F5 -> 46204
D6: מס סעיף | E6: שם סעיף | F6: סכום | G6: הערות
D7: ='דוח מרכז לאישור מנהל'!B47 -> 22620 | E7: ='דוח מרכז לאישור מנהל'!C47 -> חיוב בגין פקידת קבלה | F7: ='דוח מרכז לאישור מנהל'!D47 -> 8630
D8: ='דוח מרכז לאישור מנהל'!B48 -> 22604 | E8: ='דוח מרכז לאישור מנהל'!C48 -> חיוב שעות מאמנים | F8: ='דוח מרכז לאישור מנהל'!D48+'דוח מרכז לאישור מנהל'!D56 -> 25088.562
D9: ='דוח מרכז לאישור מנהל'!B49 -> 22660 | E9: ='דוח מרכז לאישור מנהל'!C49 -> אימונים קבוצתיים | F9: ='דוח מרכז לאישור מנהל'!D49 -> 3120
D10: ='דוח מרכז לאישור מנהל'!B60 -> 22655 | E10: ניהול מקצועי | F10: ='דוח מרכז לאישור מנהל'!D60 -> 2500
D11: ='דוח מרכז לאישור מנהל'!B50 -> 22650 | E11: ='דוח מרכז לאישור מנהל'!C50 -> אימונים אישיים | F11: ='דוח מרכז לאישור מנהל'!D54+'דוח מרכז לאישור מנהל'!D50 -> 29900
D12: ='דוח מרכז לאישור מנהל'!B52 -> 22653 | E12: אימוני סטודיו | F12: ='דוח מרכז לאישור מנהל'!D52+'דוח מרכז לאישור מנהל'!D53 -> 22140
D13: 22601 | E13: ניהול חדר כושר | F13: ='דוח מרכז לאישור מנהל'!D57+'דוח מרכז לאישור מנהל'!D58 -> 22000
D14: ='דוח מרכז לאישור מנהל'!B62 -> 22662 | E14: ='דוח מרכז לאישור מנהל'!C62 -> עמלות מכירת מנויים ושידרוגים | F14: =מכירות!N10+'דוח מרכז לאישור מנהל'!D61 -> 6416.4
E15: סך הכל | F15: =SUM(F7:F14) -> 119794.96

Sheet מכירות
B2: 46204 | C2: מועדון
B3: שם המדריך | C3: מנויים חדשים חצי שנתי | D3: עמלת מכירה מנוי | E3: חידוש מנויים /כרטיסייה/אישיים | F3: עמלת חידושים | G3: מנויים חדשים שנתי | H3: עמלת מכירה | I3: מנויים מזומן שנתי | J3: עמלת מכירה | K3: תוספות - ליווי אפליקציה | M3: סה"כ דיווח שכר | N3: סה"כ לחיוב כולל 8% ביטוח לאומי
B4: לאון | D4: 50 | E4: 21.5 | F4: 30 | G4: 10 | H4: 70 | I4: 1.5 | J4: 100 | M4: =C4*D4+E4*F4+G4*H4+I4*J4 -> 1495 | N4: =M4*1.08 -> 1614.6
B5: בר | D5: 50 | F5: 30 | H5: 70 | J5: 100 | K5: 60 | M5: =K5 -> 60 | N5: =M5*1.08 -> 64.8
B6: גלעד | D6: 50 | F6: 30 | H6: 70 | J6: 100 | K6: 180 | M6: =K6 -> 180 | N6: =M6*1.08 -> 194.4
B7: נועם | D7: 50 | E7: 28.5 | F7: 30 | G7: 12 | H7: 70 | I7: 1.5 | J7: 100 | M7: =C7*D7+E7*F7+G7*H7+I7*J7 -> 1845 | N7: =M7*1.08 -> 1992.6
B8: ערד | D8: 50 | E8: 0.5 | F8: 30 | G8: 0.5 | H8: 70 | J8: 100 | M8: =C8*D8+E8*F8+G8*H8+I8*J8 -> 50 | N8: =M8*1.08 -> 54
B9: אופל | C9: 1.5 | D9: 50 | F9: 30 | H9: 70 | J9: 100 | M9: =C9*D9+E9*F9+G9*H9+I9*J9 -> 75 | N9: =M9*1.08 -> 81
B10: סך הכל | C10: =SUM(C4:C9) -> 1.5 | E10: =SUM(E4:E9) -> 50.5 | G10: =SUM(G4:G9) -> 22.5 | I10: =SUM(I4:I9) -> 3 | J10: =SUM(J4:J9) -> 600 | K10: =SUM(K4:K9) -> 240 | M10: =SUM(M4:M9) -> 3705 | N10: =SUM(N4:N9) -> 4001.4

Sheet גיליון2
A3: תוויות שורה | B3: ספירה של תאריך
A4: אור-ים זגורי | B4: 8
A5: ברק ביטון | B5: 8
A6: דניאלה גכטמן | B6: 1
A7: זהבה מז'יבובסקי | B7: 18
A8: ליאורה נוריאל | B8: 5
A9: ליאל ויינברגר | B9: 1
A10: ליהי אברמזון | B10: 18
A11: מורן גרינשטיין | B11: 5
A12: ספיר ילינביץ' | B12: 5
A13: עדי סרי | B13: 16
A14: עמית אבן | B14: 2
A15: שמוליק בריל | B15: 1
A16: סכום כולל | B16: 88

Sheet גיליון1
A1: תאריך | B1: יום | C1: שעת התחלה | D1: שעת סיום | E1: סך שעות | F1: סך דקות | G1: סטטוס | H1: מאמן משני | I1: מאמן | J1: אימון | K1: רישומי מתאמנים | L1: אחוז תפוסה | M1: צ'ק אין | N1: רשימת המתנה | O1: סניף
A2: 43466 | B2: שלישי | C2: 0.3125 | D2: 0.34722222 | E2: 0.833 | F2: 50 | G2: מתקיים | H2: אור-ים זגורי | J2: HIIT פונקציונלי | K2: 13 | L2: 86.67 | M2: 12 | N2: 0 | O2: Alon Towers
A3: 43466 | B3: שלישי | C3: 0.77083333 | D3: 0.80555556 | E3: 0.833 | F3: 50 | G3: מתקיים | H3: זהבה מז'יבובסקי | J3: core ומתיחות | K3: 12 | L3: 100 | M3: 8 | N3: 1 | O3: Alon Towers
A4: 43466 | B4: שלישי | C4: 0.35416667 | D4: 0.38888889 | E4: 0.833 | F4: 50 | G4: מתקיים | H4: ליהי אברמזון | J4: יוגה | K4: 12 | L4: 100 | M4: 10 | N4: 5 | O4: Alon Towers
A5: 43466 | B5: שלישי | C5: 0.72916667 | D5: 0.76388889 | E5: 0.833 | F5: 50 | G5: מתקיים | H5: ליאורה נוריאל | J5: Kickbox | K5: 14 | L5: 93.33 | M5: 11 | N5: 0 | O5: Alon Towers
A6: 43467 | B6: רביעי | C6: 0.77083333 | D6: 0.80555556 | E6: 0.833 | F6: 50 | G6: מתקיים | H6: עדי סרי | J6: Alon Skill | K6: 15 | L6: 100 | M6: 11 | N6: 10 | O6: Alon Towers
A7: 43467 | B7: רביעי | C7: 0.3125 | D7: 0.34722222 | E7: 0.833 | F7: 50 | G7: מתקיים | H7: ליאל ויינברגר | J7: יוגה | K7: 12 | L7: 100 | M7: 6 | N7: 0 | O7: Alon Towers
A8: 43467 | B8: רביעי | C8: 0.72916667 | D8: 0.76388889 | E8: 0.833 | F8: 50 | G8: מתקיים | H8: עדי סרי | J8: פילאטיס | K8: 10 | L8: 100 | M8: 8 | N8: 11 | O8: Alon Towers
A9: 43468 | B9: חמישי | C9: 0.35416667 | D9: 0.38888889 | E9: 0.833 | F9: 50 | G9: מתקיים | H9: ספיר ילינביץ' | J9: פילאטיס | K9: 10 | L9: 100 | M9: 8 | N9: 2 | O9: Alon Towers
A10: 43468 | B10: חמישי | C10: 0.72916667 | D10: 0.76388889 | E10: 0.833 | F10: 50 | G10: מתקיים | H10: ליהי אברמזון | J10: Power Yoga | K10: 12 | L10: 100 | M10: 9 | N10: 5 | O10: Alon Towers
A11: 43468 | B11: חמישי | C11: 0.77083333 | D11: 0.80555556 | E11: 0.833 | F11: 50 | G11: מתקיים | H11: ברק ביטון | J11: Ouotdoor Functional | K11: 20 | L11: 100 | M11: 18 | N11: 0 | O11: Alon Towers
A12: 43468 | B12: חמישי | C12: 0.3125 | D12: 0.34722222 | E12: 0.833 | F12: 50 | G12: מתקיים | H12: זהבה מז'יבובסקי | J12: HIIT TRX | K12: 11 | L12: 78.57 | M12: 9 | N12: 0 | O12: Alon Towers
A13: 43471 | B13: ראשון | C13: 0.35416667 | D13: 0.38888889 | E13: 0.833 | F13: 50 | G13: מתקיים | H13: ליהי אברמזון | J13: יוגה | K13: 12 | L13: 100 | M13: 12 | N13: 5 | O13: Alon Towers
... A89: 43496 | B89: חמישי | C89: 0.35416667 | D89: 0.38888889 | E89: 0.833 | F89: 50 | G89: מתקיים | H89: ספיר ילינביץ' | J89: פילאטיס | K89: 11 | L89: 91.67 | M89: 10 | N89: 1 | O89: Alon Towers

Sheet חגים
A1: תאריך | B1: תיאור אירוע | C1: סוג אירוע
A2: 39721 | B2: ראש השנה א' | C2: חגים דתיים
A3: 39722 | B3: ראש השנה ב' | C3: חגים דתיים
A4: 39723 | B4: צום גדליה | C4: חגים דתיים
A5: 39729 | B5: ערב יום כיפור | C5: חגים דתיים
A6: 39730 | B6: יום כיפור | C6: חגים דתיים
A7: 39734 | B7: ערב סוכות | C7: חגים דתיים
A8: 39735 | B8: סוכות | C8: חגים דתיים
A9: 39736 | B9: חול המועד סוכות (1) | C9: חגים דתיים
A10: 39737 | B10: חול המועד סוכות (2) | C10: חגים דתיים
A11: 39738 | B11: חול המועד סוכות (3) | C11: חגים דתיים
A12: 39739 | B12: חול המועד סוכות (4) | C12: חגים דתיים
A13: 39740 | B13: חול המועד סוכות (5) | C13: חגים דתיים
... A794: 46795 | B794: ט"ו בשבט | C794: חגים דתיים

Sheet דוח אימוני סטודיו
A1: תאריך | B1: יום | C1: שעת התחלה | D1: שעת סיום | E1: סך שעות | F1: סך דקות | G1: סטטוס | H1: מאמן משני | I1: מאמן | J1: אימון | K1: רישומי מתאמנים | L1: צ'ק אין | M1: רשימת המתנה | N1: סניף
A2: 43405 | B2: חמישי | C2: 0.33333333 | D2: 0.36805556 | E2: 0.833 | F2: 50 | G2: מתקיים | H2: זהבה מז'יבובסקי | J2: HIIT TRX | K2: 7 | L2: 7 | M2: 17 | N2: Alon Towers
A3: 43405 | B3: חמישי | C3: 0.75 | D3: 0.78472222 | E3: 0.833 | F3: 50 | G3: מתקיים | J3: יוגה | K3: 10 | L3: 6 | M3: 31 | N3: Alon Towers
A4: 43408 | B4: ראשון | C4: 0.35416667 | D4: 0.38888889 | E4: 0.833 | F4: 50 | G4: מתקיים | J4: יוגה | K4: 10 | L4: 0 | M4: 6 | N4: Alon Towers | P4: ספירה של תאריך | Q4: תוויות עמודה
A5: 43408 | B5: ראשון | C5: 0.75 | D5: 0.78472222 | E5: 0.833 | F5: 50 | G5: מתקיים | H5: עדי סרי | J5: ALON SKILL | K5: 12 | L5: 11 | M5: 0 | N5: Alon Towers | P5: תוויות שורה | Q5: השיעור בוטל | R5: מתקיים | S5: סכום כולל
A6: 43408 | B6: ראשון | C6: 0.79166667 | D6: 0.82638889 | E6: 0.833 | F6: 50 | G6: מתקיים | H6: ברק ביטון | J6: HIIT TRX | K6: 9 | L6: 9 | M6: 0 | N6: Alon Towers | R6: 3 | S6: 3
A7: 43409 | B7: שני | C7: 0.3125 | D7: 0.34722222 | E7: 0.833 | F7: 50 | G7: מתקיים | H7: עדי סרי | J7: פילאטיס | K7: 9 | L7: 8 | M7: 0 | N7: Alon Towers | P7: אור-ים זגורי | R7: 4 | S7: 4
A8: 43409 | B8: שני | C8: 0.35416667 | D8: 0.38888889 | E8: 0.833 | F8: 50 | G8: מתקיים | H8: רועי עתריה | J8: HIIT פונקציונלי | K8: 10 | L8: 9 | M8: 0 | N8: Alon Towers | P8: ברק ביטון | R8: 7 | S8: 7
A9: 43409 | B9: שני | C9: 0.79166667 | D9: 0.82638889 | E9: 0.833 | F9: 50 | G9: מתקיים | J9: יוגה | K9: 10 | L9: 8 | M9: 6 | N9: Alon Towers | P9: גיל בקמן | R9: 9 | S9: 9
A10: 43410 | B10: שלישי | C10: 0.75 | D10: 0.78472222 | E10: 0.833 | F10: 50 | G10: מתקיים | H10: מורן גרינשטיין | J10: HIIT פונקציונלי | K10: 12 | L10: 9 | M10: 0 | N10: Alon Towers | P10: זהבה מז'יבובסקי | Q10: 1 | R10: 9 | S10: 10
A11: 43410 | B11: שלישי | C11: 0.3125 | D11: 0.34722222 | E11: 0.833 | F11: 50 | G11: מתקיים | H11: גיל בקמן | J11: יוגה | K11: 5 | L11: 3 | M11: 0 | N11: Alon Towers | P11: ליהי אברמזון | R11: 7 | S11: 7
A12: 43410 | B12: שלישי | C12: 0.35416667 | D12: 0.38888889 | E12: 0.833 | F12: 50 | G12: מתקיים | H12: אור-ים זגורי | J12: HIIT TRX | K12: 6 | L12: 4 | M12: 0 | N12: Alon Towers | P12: מורן גרינשטיין | R12: 4 | S12: 4
A13: 43411 | B13: רביעי | C13: 0.75 | D13: 0.78472222 | E13: 0.833 | F13: 50 | G13: מתקיים | H13: עדי סרי | J13: פילאטיס | K13: 10 | L13: 9 | M13: 12 | N13: Alon Towers | P13: מתן הלוי | R13: 2 | S13: 2
A14: 43411 | B14: רביעי | C14: 0.3125 | D14: 0.34722222 | E14: 0.833 | F14: 50 | G14: מתקיים | H14: זהבה מז'יבובסקי | J14: HIIT פונקציונלי | K14: 11 | L14: 8 | M14: 0 | N14: Alon Towers | P14: עדי סרי | R14: 19 | S14: 19
A15: 43411 | B15: רביעי | C15: 0.79166667 | D15: 0.82638889 | E15: 0.833 | F15: 50 | G15: מתקיים | H15: עדי סרי | J15: ALON SKILL | K15: 14 | L15: 12 | M15: 0 | N15: Alon Towers | P15: רועי עתריה | Q15: 1 | R15: 3 | S15: 4
A16: 43412 | B16: חמישי | C16: 0.35416667 | D16: 0.38888889 | E16: 0.833 | F16: 50 | G16: מתקיים | H16: זהבה מז'יבובסקי | J16: ALON SKILL | K16: 12 | L16: 12 | M16: 0 | N16: Alon Towers | P16: סכום כולל | Q16: 2 | R16: 67 | S16: 69
A17: 43412 | B17: חמישי | C17: 0.75 | D17: 0.78472222 | E17: 0.833 | F17: 50 | G17: מתקיים | H17: ליהי אברמזון | J17: יוגה | K17: 11 | L17: 8 | M17: 16 | N17: Alon Towers
A18: 43412 | B18: חמישי | C18: 0.79166667 | D18: 0.82638889 | E18: 0.833 | F18: 50 | G18: מתקיים | H18: ברק ביטון | J18: OUTDOOR FUNCTIONAL | K18: 10 | L18: 7 | M18: 0 | N18: Alon Towers
A19: 43415 | B19: ראשון | C19: 0.3125 | D19: 0.34722222 | E19: 0.833 | F19: 50 | G19: מתקיים | H19: ליהי אברמזון | J19: יוגה | K19: 10 | L19: 10 | M19: 0 | N19: Alon Towers
A20: 43415 | B20: ראשון | C20: 0.75 | D20: 0.78472222 | E20: 0.833 | F20: 50 | G20: מתקיים | H20: מתן הלוי | J20: KICK AND SHAPE | K20: 10 | L20: 10 | M20: 0 | N20: Alon Towers
A21: 43415 | B21: ראשון | C21: 0.79166667 | D21: 0.82638889 | E21: 0.833 | F21: 50 | G21: מתקיים | H21: עדי סרי | J21: פילאטיס | K21: 9 | L21: 8 | M21: 0 | N21: Alon Towers
A22: 43416 | B22: שני | C22: 0.3125 | D22: 0.34722222 | E22: 0.833 | F22: 50 | G22: מתקיים | H22: עדי סרי | J22: פילאטיס | K22: 10 | L22: 9 | M22: 0 | N22: Alon Towers
A23: 43416 | B23: שני | C23: 0.35416667 | D23: 0.38888889 | E23: 0.833 | F23: 50 | G23: מתקיים | H23: עדי סרי | J23: ALON SKILL | K23: 11 | L23: 10 | M23: 0 | N23: Alon Towers
A24: 43416 | B24: שני | C24: 0.75 | D24: 0.78472222 | E24: 0.833 | F24: 50 | G24: מתקיים | H24: מורן גרינשטיין | J24: HIIT TRX | K24: 7 | L24: 7 | M24: 0 | N24: Alon Towers
A25: 43416 | B25: שני | C25: 0.79166667 | D25: 0.82638889 | E25: 0.833 | F25: 50 | G25: מתקיים | H25: ליהי אברמזון | J25: יוגה | K25: 10 | L25: 8 | M25: 10 | N25: Alon Towers
A26: 43417 | B26: שלישי | C26: 0.35416667 | D26: 0.38888889 | E26: 0.833 | F26: 50 | G26: מתקיים | H26: רועי עתריה | J26: HIIT פונקציונלי | K26: 6 | L26: 5 | M26: 0 | N26: Alon Towers
A27: 43417 | B27: שלישי | C27: 0.75 | D27: 0.78472222 | E27: 0.833 | F27: 50 | G27: מתקיים | H27: ברק ביטון | J27: OUTDOOR FUNCTIONAL | K27: 12 | L27: 10 | M27: 0 | N27: Alon Towers
A28: 43417 | B28: שלישי | C28: 0.79166667 | D28: 0.82638889 | E28: 0.833 | F28: 50 | G28: השיעור בוטל | H28: זהבה מז'יבובסקי | J28: ALON SKILL | K28: 0 | L28: 0 | M28: 0 | N28: Alon Towers
... A70: 43433 | B70: חמישי | C70: 0.3125 | D70: 0.34722222 | E70: 0.833 | F70: 50 | G70: מתקיים | H70: זהבה מז'יבובסקי | J70: core ומתיחות | K70: 10 | L70: 6 | M70: 0 | N70: Alon Towers
